File: LAB 1 - Deformation (tensile test)/FDcurve_specimen1.txt
Time(s),Crosshead(mm),Load(kN),Extensometer(mm/mm),Stress(MPa)
1.2,0.0015,0.273,0.00001,21.504
1.5,0.0062,0.330,0.00003,25.966
1.8,0.0110,0.387,0.00005,30.491
2.1,0.0159,0.442,0.00007,34.829
2.4,0.0207,0.493,0.00009,38.844
2.7,0.0256,0.545,0.00011,42.888
3.0,0.0307,0.596,0.00013,46.899
3.3,0.0359,0.644,0.00015,50.686
3.6,0.0410,0.690,0.00017,54.315
3.9,0.0459,0.732,0.00018,57.609
4.2,0.0509,0.773,0.00020,60.842
4.5,0.0560,0.814,0.00022,64.064
4.8,0.0611,0.853,0.00024,67.142
5.1,0.0661,0.891,0.00025,70.171
5.4,0.0710,0.927,0.00026,72.987
5.7,0.0759,0.962,0.00027,75.704
6.0,0.0810,0.996,0.00028,78.400
6.3,0.0860,1.029,0.00030,81.040
6.6,0.0911,1.062,0.00031,83.595
6.9,0.0960,1.093,0.00032,86.084
7.2,0.1011,1.125,0.00034,88.570
7.5,0.1060,1.156,0.00035,91.039
7.8,0.1111,1.187,0.00036,93.449
8.1,0.1159,1.216,0.00037,95.735
8.4,0.1209,1.243,0.00038,97.863
8.7,0.1259,1.271,0.00039,100.024
9.0,0.1309,1.300,0.00040,102.312
9.3,0.1360,1.326,0.00041,104.419
9.6,0.1409,1.353,0.00042,106.487
9.9,0.1459,1.379,0.00043,108.580
10.2,0.1510,1.407,0.00045,110.761
10.5,0.1560,1.435,0.00046,112.971
10.8,0.1611,1.463,0.00047,115.168
11.1,0.1661,1.489,0.00048,117.218
11.4,0.1710,1.515,0.00049,119.294
11.7,0.1760,1.543,0.00050,121.443
12.0,0.1811,1.570,0.00051,123.611
12.3,0.1861,1.598,0.00053,125.770
12.6,0.1909,1.624,0.00054,127.835
12.9,0.1959,1.650,0.00055,129.919
13.2,0.2009,1.677,0.00056,132.061
13.5,0.2059,1.706,0.00058,134.321
13.8,0.2110,1.735,0.00058,136.550
14.1,0.2158,1.760,0.00060,138.571
14.4,0.2208,1.788,0.00061,140.780
14.7,0.2259,1.815,0.00062,142.926
15.0,0.2309,1.845,0.00063,145.225
15.3,0.2359,1.872,0.00064,147.367
15.6,0.2408,1.898,0.00065,149.441
15.9,0.2459,1.925,0.00066,151.567
16.2,0.2508,1.954,0.00068,153.804
16.5,0.2559,1.981,0.00069,155.938
16.8,0.2608,2.007,0.00070,158.024
17.1,0.2658,2.033,0.00072,160.077
17.4,0.2708,2.060,0.00073,162.193
17.7,0.2758,2.088,0.00074,164.346
18.0,0.2808,2.114,0.00075,166.451
18.3,0.2857,2.139,0.00076,168.414
18.6,0.2907,2.165,0.00078,170.423
18.9,0.2959,2.192,0.00079,172.602
19.2,0.3008,2.219,0.00080,174.684
19.5,0.3059,2.245,0.00081,176.726
19.8,0.3107,2.269,0.00083,178.655
20.1,0.3157,2.295,0.00083,180.678
20.4,0.3207,2.321,0.00085,182.753
20.7,0.3257,2.349,0.00086,184.908
21.0,0.3308,2.376,0.00088,187.075
21.3,0.3357,2.402,0.00088,189.074
21.6,0.3407,2.428,0.00089,191.139
21.9,0.3458,2.454,0.00091,193.198
22.2,0.3508,2.481,0.00092,195.312
22.5,0.3559,2.507,0.00094,197.371
22.8,0.3607,2.532,0.00095,199.338
23.1,0.3658,2.558,0.00096,201.380
23.4,0.3706,2.583,0.00097,203.358
23.7,0.3756,2.610,0.00099,205.460
24.0,0.3805,2.636,0.00100,207.486
24.3,0.3855,2.662,0.00101,209.536
24.6,0.3906,2.689,0.00102,211.671
24.9,0.3956,2.716,0.00104,213.821
25.2,0.4007,2.743,0.00106,215.952
25.5,0.4056,2.769,0.00107,218.020
25.8,0.4107,2.795,0.00108,220.043
26.1,0.4156,2.822,0.00110,222.150
26.4,0.4207,2.849,0.00111,224.317
26.7,0.4258,2.877,0.00113,226.476
27.0,0.4307,2.902,0.00114,228.485
27.3,0.4355,2.928,0.00115,230.481
27.6,0.4405,2.955,0.00116,232.599
27.9,0.4455,2.982,0.00118,234.726
28.2,0.4505,3.009,0.00120,236.890
28.5,0.4554,3.035,0.00121,238.971
28.8,0.4604,3.062,0.00122,241.032
29.1,0.4655,3.089,0.00124,243.214
29.4,0.4706,3.117,0.00125,245.413
29.7,0.4756,3.145,0.00127,247.559
30.0,0.4804,3.170,0.00128,249.576
30.3,0.4855,3.198,0.00130,251.730
30.6,0.4904,3.225,0.00131,253.882
30.9,0.4956,3.252,0.00133,256.021
31.2,0.5006,3.281,0.00134,258.280
31.5,0.5055,3.306,0.00136,260.303
31.8,0.5105,3.334,0.00137,262.459
32.1,0.5155,3.361,0.00139,264.612
32.4,0.5206,3.390,0.00141,266.848
32.7,0.5255,3.417,0.00142,269.013
33.0,0.5305,3.444,0.00144,271.103
33.3,0.5355,3.471,0.00145,273.296
33.6,0.5405,3.499,0.00147,275.450
33.9,0.5455,3.528,0.00149,277.705
34.2,0.5505,3.554,0.00150,279.812
34.5,0.5555,3.582,0.00152,281.966
34.8,0.5606,3.610,0.00153,284.184
35.1,0.5655,3.637,0.00155,286.349
35.4,0.5707,3.666,0.00157,288.622
35.7,0.5755,3.692,0.00158,290.654
36.0,0.5804,3.719,0.00160,292.769
36.3,0.5854,3.747,0.00162,294.950
36.6,0.5903,3.774,0.00163,297.104
36.9,0.5954,3.803,0.00165,299.363
37.2,0.6003,3.829,0.00167,301.465
37.5,0.6052,3.857,0.00169,303.619
37.8,0.6103,3.885,0.00171,305.816
38.1,0.6152,3.911,0.00173,307.915
38.4,0.6203,3.940,0.00174,310.162
38.7,0.6253,3.968,0.00176,312.412
39.0,0.6304,3.997,0.00177,314.675
39.3,0.6355,4.024,0.00180,316.788
39.6,0.6404,4.052,0.00182,318.964
39.9,0.6454,4.079,0.00183,321.095
40.2,0.6503,4.105,0.00186,323.201
40.5,0.6552,4.134,0.00187,325.419
40.8,0.6602,4.161,0.00189,327.601
41.1,0.6653,4.190,0.00192,329.862
41.4,0.6703,4.218,0.00193,332.029
41.7,0.6753,4.245,0.00195,334.162
42.0,0.6803,4.272,0.00196,336.286
42.3,0.6852,4.300,0.00199,338.489
42.6,0.6903,4.328,0.00201,340.762
42.9,0.6952,4.355,0.00203,342.832
43.2,0.7002,4.382,0.00204,344.961
43.5,0.7052,4.410,0.00207,347.155
43.8,0.7103,4.438,0.00209,349.412
44.1,0.7154,4.468,0.00211,351.707
44.4,0.7203,4.493,0.00214,353.692
44.7,0.7252,4.520,0.00215,355.850
45.0,0.7303,4.547,0.00217,358.001
45.3,0.7353,4.576,0.00219,360.235
45.6,0.7403,4.603,0.00222,362.401
45.9,0.7451,4.629,0.00224,364.389
46.2,0.7501,4.656,0.00226,366.573
46.5,0.7551,4.684,0.00229,368.766
46.8,0.7602,4.711,0.00231,370.916
47.1,0.7652,4.738,0.00233,372.984
47.4,0.7702,4.765,0.00235,375.094
47.7,0.7752,4.793,0.00238,377.305
48.0,0.7803,4.820,0.00240,379.448
48.3,0.7852,4.845,0.00242,381.465
48.6,0.7901,4.872,0.00244,383.545
48.9,0.7951,4.898,0.00247,385.606
49.2,0.8002,4.925,0.00249,387.754
49.5,0.8051,4.952,0.00252,389.880
49.8,0.8102,4.979,0.00254,391.952
50.1,0.8151,5.004,0.00257,393.931
50.4,0.8201,5.029,0.00259,395.923
50.7,0.8252,5.057,0.00261,398.132
51.0,0.8303,5.084,0.00264,400.255
51.3,0.8353,5.110,0.00266,402.315
51.6,0.8402,5.134,0.00269,404.190
51.9,0.8451,5.159,0.00272,406.130
52.2,0.8500,5.184,0.00274,408.133
52.5,0.8551,5.211,0.00277,410.205
52.8,0.8602,5.237,0.00279,412.300
53.1,0.8650,5.261,0.00282,414.162
53.4,0.8699,5.285,0.00285,416.104
53.7,0.8750,5.311,0.00287,418.109
54.0,0.8799,5.336,0.00290,420.105
54.3,0.8849,5.361,0.00293,422.035
54.6,0.8898,5.384,0.00296,423.883
54.9,0.8949,5.410,0.00299,425.902
55.2,0.8999,5.435,0.00301,427.900
55.5,0.9050,5.460,0.00304,429.811
55.8,0.9100,5.482,0.00307,431.613
56.1,0.9150,5.507,0.00310,433.538
56.4,0.9200,5.532,0.00313,435.478
56.7,0.9251,5.556,0.00316,437.377
57.0,0.9300,5.579,0.00319,439.242
57.3,0.9350,5.601,0.00322,440.980
57.6,0.9399,5.623,0.00326,442.688
57.9,0.9448,5.646,0.00328,444.455
58.2,0.9498,5.669,0.00331,446.313
58.5,0.9547,5.691,0.00334,448.047
58.8,0.9597,5.714,0.00338,449.872
59.1,0.9647,5.737,0.00340,451.687
59.4,0.9698,5.760,0.00344,453.442
59.7,0.9749,5.784,0.00348,455.319
60.0,0.9799,5.803,0.00351,456.862
60.3,0.9848,5.824,0.00354,458.490
60.6,0.9899,5.847,0.00357,460.293
60.9,0.9950,5.869,0.00361,462.070
61.2,1.0000,5.891,0.00364,463.759
61.5,1.0048,5.908,0.00367,465.133
61.8,1.0098,5.929,0.00371,466.789
62.1,1.0148,5.949,0.00374,468.374
62.4,1.0199,5.972,0.00378,470.113
62.7,1.0248,5.992,0.00382,471.747
63.0,1.0298,6.010,0.00385,473.177
63.3,1.0348,6.031,0.00389,474.832
63.6,1.0399,6.050,0.00392,476.323
63.9,1.0451,6.071,0.00396,477.963
64.2,1.0500,6.090,0.00400,479.415
64.5,1.0550,6.108,0.00404,480.859
64.8,1.0600,6.127,0.00408,482.359
65.1,1.0651,6.145,0.00412,483.800
65.4,1.0702,6.165,0.00415,485.335
65.7,1.0751,6.181,0.00419,486.615
66.0,1.0800,6.198,0.00423,487.948
66.3,1.0851,6.216,0.00428,489.358
66.6,1.0900,6.233,0.00432,490.714
66.9,1.0951,6.251,0.00436,492.102
67.2,1.0997,6.264,0.00440,493.141
67.5,1.1045,6.279,0.00444,494.286
67.8,1.1095,6.296,0.00448,495.619
68.1,1.1145,6.314,0.00452,497.043
68.4,1.1195,6.330,0.00457,498.323
68.7,1.1245,6.344,0.00461,499.474
69.0,1.1295,6.361,0.00465,500.766
69.3,1.1346,6.377,0.00469,502.013
69.6,1.1397,6.392,0.00474,503.208
69.9,1.1447,6.406,0.00479,504.319
70.2,1.1497,6.420,0.00483,505.395
70.5,1.1549,6.435,0.00488,506.624
70.8,1.1600,6.449,0.00493,507.737
71.1,1.1652,6.464,0.00498,508.863
71.4,1.1703,6.478,0.00502,509.967
71.7,1.1752,6.489,0.00507,510.880
72.0,1.1803,6.501,0.00512,511.824
72.3,1.1852,6.513,0.00517,512.716
72.6,1.1902,6.525,0.00522,513.680
72.9,1.1948,6.535,0.00526,514.507
73.2,1.1996,6.546,0.00532,515.360
73.5,1.2046,6.558,0.00536,516.245
73.8,1.2095,6.570,0.00541,517.238
74.1,1.2143,6.580,0.00547,518.037
74.4,1.2192,6.591,0.00551,518.894
74.7,1.2243,6.605,0.00556,519.949
75.0,1.2295,6.615,0.00562,520.772
75.3,1.2346,6.627,0.00567,521.737
75.6,1.2395,6.636,0.00572,522.400
75.9,1.2445,6.646,0.00577,523.172
76.2,1.2495,6.656,0.00582,524.016
76.5,1.2546,6.666,0.00588,524.821
76.8,1.2597,6.676,0.00593,525.591
77.1,1.2647,6.683,0.00599,526.128
77.4,1.2696,6.691,0.00605,526.778
77.7,1.2747,6.701,0.00610,527.502
78.0,1.2797,6.710,0.00616,528.238
78.3,1.2847,6.718,0.00621,528.877
78.6,1.2896,6.725,0.00627,529.399
78.9,1.2946,6.733,0.00632,530.076
79.2,1.2996,6.741,0.00638,530.672
79.5,1.3047,6.749,0.00644,531.343
79.8,1.3096,6.757,0.00650,531.963
80.1,1.3145,6.764,0.00656,532.478
80.4,1.3195,6.771,0.00662,533.036
80.7,1.3246,6.777,0.00667,533.536
81.0,1.3297,6.786,0.00673,534.245
81.3,1.3347,6.793,0.00679,534.749
81.6,1.3396,6.798,0.00685,535.157
81.9,1.3446,6.805,0.00690,535.703
82.2,1.3496,6.810,0.00696,536.151
82.5,1.3547,6.818,0.00703,536.720
82.8,1.3598,6.824,0.00710,537.213
83.1,1.3647,6.828,0.00715,537.526
83.4,1.3695,6.834,0.00720,538.013
83.7,1.3746,6.840,0.00727,538.461
84.0,1.3796,6.847,0.00733,538.999
84.3,1.3846,6.849,0.00740,539.198
84.6,1.3895,6.854,0.00745,539.622
84.9,1.3946,6.861,0.00752,540.103
85.2,1.3996,6.867,0.00758,540.594
85.5,1.4047,6.873,0.00764,541.055
85.8,1.4095,6.874,0.00771,541.159
86.1,1.4145,6.880,0.00777,541.641
86.4,1.4196,6.884,0.00784,541.974
86.7,1.4247,6.890,0.00789,542.443
87.0,1.4297,6.896,0.00796,542.854
87.3,1.4346,6.898,0.00802,543.017
87.6,1.4396,6.902,0.00809,543.387
87.9,1.4446,6.906,0.00816,543.647
88.2,1.4497,6.911,0.00822,544.100
88.5,1.4547,6.915,0.00828,544.375
88.8,1.4595,6.917,0.00835,544.562
89.1,1.4646,6.922,0.00841,544.947
89.4,1.4695,6.925,0.00848,545.206
89.7,1.4746,6.931,0.00854,545.622
90.0,1.4795,6.933,0.00860,545.829
90.3,1.4845,6.936,0.00867,546.025
90.6,1.4896,6.942,0.00874,546.480
90.9,1.4947,6.946,0.00880,546.793
91.2,1.4998,6.949,0.00887,547.096
91.5,1.5047,6.950,0.00894,547.172
91.8,1.5096,6.953,0.00901,547.368
92.1,1.5146,6.956,0.00907,547.615
92.4,1.5196,6.960,0.00914,547.939
92.7,1.5247,6.965,0.00921,548.324
93.0,1.5296,6.967,0.00928,548.469
93.3,1.5347,6.970,0.00934,548.709
93.6,1.5398,6.973,0.00941,548.980
93.9,1.5448,6.977,0.00948,549.263
94.2,1.5499,6.980,0.00955,549.526
94.5,1.5547,6.981,0.00961,549.589
94.8,1.5597,6.984,0.00968,549.852
95.1,1.5646,6.985,0.00974,549.899
95.4,1.5695,6.989,0.00981,550.192
95.7,1.5746,6.992,0.00988,550.412
96.0,1.5795,6.994,0.00994,550.581
96.3,1.5845,6.998,0.01002,550.920
96.6,1.5895,7.000,0.01009,551.077
96.9,1.5947,7.004,0.01015,551.373
97.2,1.5997,7.006,0.01022,551.552
97.5,1.6047,7.008,0.01029,551.701
97.8,1.6096,7.011,0.01035,551.920
98.1,1.6146,7.013,0.01042,552.075
98.4,1.6197,7.017,0.01049,552.411
98.7,1.6247,7.018,0.01056,552.470
99.0,1.6295,7.019,0.01062,552.579
99.3,1.6345,7.021,0.01069,552.728
99.6,1.6395,7.024,0.01077,553.002
99.9,1.6445,7.028,0.01083,553.247
100.2,1.6493,7.029,0.01090,553.367
100.5,1.6543,7.031,0.01097,553.512
100.8,1.6595,7.033,0.01104,553.686
101.1,1.6645,7.037,0.01111,553.996
101.4,1.6695,7.039,0.01117,554.167
101.7,1.6744,7.040,0.01124,554.231
102.0,1.6795,7.043,0.01131,554.453
102.3,1.6844,7.045,0.01138,554.656
102.6,1.6895,7.048,0.01145,554.873
102.9,1.6946,7.051,0.01152,555.075
103.2,1.6995,7.051,0.01159,555.122
103.5,1.7046,7.054,0.01166,555.341
103.8,1.7095,7.055,0.01173,555.445
104.1,1.7147,7.059,0.01180,555.699
104.4,1.7196,7.060,0.01187,555.775
104.7,1.7246,7.061,0.01194,555.876
105.0,1.7296,7.064,0.01201,556.097
105.3,1.7346,7.065,0.01208,556.225
105.6,1.7396,7.069,0.01215,556.536
105.9,1.7447,7.070,0.01222,556.605
106.2,1.7496,7.071,0.01229,556.679
106.5,1.7547,7.074,0.01236,556.925
106.8,1.7598,7.077,0.01242,557.128
107.1,1.7648,7.079,0.01250,557.334
107.4,1.7697,7.079,0.01257,557.281
107.7,1.7747,7.080,0.01264,557.349
108.0,1.7796,7.082,0.01270,557.518
108.3,1.7846,7.084,0.01277,557.710
108.6,1.7896,7.087,0.01284,557.919
108.9,1.7944,7.088,0.01291,558.015
109.2,1.7995,7.089,0.01298,558.110
109.5,1.8045,7.092,0.01305,558.292
109.8,1.8095,7.094,0.01312,558.467
110.1,1.8146,7.096,0.01319,558.649
110.4,1.8195,7.098,0.01326,558.783
110.7,1.8247,7.101,0.01333,558.997
111.0,1.8297,7.101,0.01340,559.036
111.3,1.8347,7.103,0.01347,559.201
111.6,1.8396,7.104,0.01354,559.287
111.9,1.8445,7.104,0.01361,559.301
112.2,1.8495,7.108,0.01368,559.544
112.5,1.8544,7.109,0.01375,559.655
112.8,1.8595,7.111,0.01381,559.806
113.1,1.8644,7.113,0.01389,559.950
113.4,1.8695,7.115,0.01396,560.113
113.7,1.8745,7.116,0.01403,560.220
114.0,1.8795,7.118,0.01410,560.363
114.3,1.8846,7.121,0.01417,560.621
114.6,1.8895,7.122,0.01425,560.700
114.9,1.8944,7.122,0.01431,560.694
115.2,1.8995,7.124,0.01438,560.865
115.5,1.9046,7.127,0.01445,561.092
115.8,1.9097,7.130,0.01452,561.310
116.1,1.9147,7.130,0.01459,561.340
116.4,1.9197,7.132,0.01466,561.447
116.7,1.9247,7.133,0.01473,561.531
117.0,1.9298,7.135,0.01480,561.732
117.3,1.9348,7.137,0.01487,561.837
117.6,1.9395,7.137,0.01494,561.852
117.9,1.9438,7.137,0.01500,561.884
137.5,1.9438,6.761,0.17473,532.277
137.8,1.9876,7.276,0.17475,572.814
138.1,2.0377,7.402,0.17474,582.694
138.4,2.0874,7.404,0.17475,582.855
138.7,2.1377,7.407,0.17475,583.087
139.0,2.1876,7.417,0.17476,583.942
139.3,2.2380,7.428,0.17476,584.740
139.6,2.2882,7.437,0.17475,585.515
139.9,2.3376,7.449,0.17476,586.432
140.2,2.3883,7.458,0.17474,587.133
140.5,2.4375,7.471,0.17475,588.168
140.8,2.4877,7.482,0.17475,589.062
141.1,2.5376,7.494,0.17475,589.994
141.4,2.5877,7.506,0.17474,590.897
141.7,2.6379,7.518,0.17476,591.836
142.0,2.6879,7.532,0.17477,592.945
142.3,2.7380,7.542,0.17476,593.778
142.6,2.7877,7.553,0.17477,594.652
142.9,2.8375,7.562,0.17477,595.361
143.2,2.8876,7.576,0.17476,596.435
143.5,2.9379,7.587,0.17476,597.318
143.8,2.9876,7.596,0.17477,597.976
144.1,3.0378,7.609,0.17476,599.052
144.4,3.0878,7.620,0.17476,599.895
144.7,3.1378,7.629,0.17476,600.607
145.0,3.1875,7.642,0.17477,601.607
145.3,3.2378,7.653,0.17474,602.491
145.6,3.2875,7.664,0.17479,603.354
145.9,3.3375,7.672,0.17478,603.997
146.2,3.3878,7.686,0.17478,605.099
146.5,3.4379,7.696,0.17479,605.882
146.8,3.4878,7.705,0.17478,606.601
147.1,3.5375,7.717,0.17476,607.528
147.4,3.5880,7.725,0.17477,608.172
147.7,3.6375,7.736,0.17476,609.027
148.0,3.6879,7.748,0.17475,609.964
148.3,3.7376,7.756,0.17478,610.582
148.6,3.7877,7.766,0.17478,611.394
148.9,3.8378,7.777,0.17479,612.251
149.2,3.8879,7.788,0.17479,613.109
149.5,3.9379,7.797,0.17480,613.828
149.8,3.9877,7.807,0.17480,614.604
150.1,4.0375,7.814,0.17480,615.132
150.4,4.0877,7.825,0.17481,616.032
150.7,4.1376,7.835,0.17478,616.801
151.0,4.1875,7.843,0.17478,617.422
151.3,4.2375,7.852,0.17479,618.118
151.6,4.2875,7.862,0.17478,618.962
151.9,4.3374,7.870,0.17477,619.538
152.2,4.3875,7.880,0.17479,620.390
152.5,4.4375,7.891,0.17478,621.191
152.8,4.4873,7.900,0.17480,621.941
153.1,4.5373,7.907,0.17482,622.478
153.4,4.5875,7.919,0.17482,623.462
153.7,4.6377,7.927,0.17480,624.096
154.0,4.6875,7.934,0.17481,624.605
154.3,4.7375,7.946,0.17480,625.530
154.6,4.7875,7.950,0.17478,625.877
154.9,4.8374,7.963,0.17478,626.861
155.2,4.8875,7.971,0.17479,627.548
155.5,4.9376,7.980,0.17479,628.258
155.8,4.9874,7.987,0.17480,628.801
156.1,5.0377,7.997,0.17483,629.543
156.4,5.0876,8.006,0.17482,630.309
156.7,5.1378,8.014,0.17482,630.933
157.0,5.1876,8.023,0.17481,631.584
157.3,5.2374,8.028,0.17481,632.049
157.6,5.2875,8.039,0.17479,632.884
157.9,5.3379,8.048,0.17481,633.603
158.2,5.3875,8.055,0.17479,634.099
158.5,5.4375,8.062,0.17480,634.713
158.8,5.4875,8.073,0.17481,635.536
159.1,5.5375,8.080,0.17483,636.077
159.4,5.5874,8.088,0.17483,636.772
159.7,5.6375,8.097,0.17484,637.425
160.0,5.6875,8.105,0.17484,638.091
160.3,5.7374,8.111,0.17482,638.581
160.6,5.7876,8.122,0.17481,639.381
160.9,5.8379,8.129,0.17481,639.934
161.2,5.8874,8.133,0.17480,640.258
161.5,5.9375,8.146,0.17480,641.321
161.8,5.9875,8.148,0.17481,641.450
162.1,6.0375,8.163,0.17482,642.603
162.4,6.0875,8.168,0.17484,643.010
162.7,6.1376,8.177,0.17484,643.713
163.0,6.1875,8.182,0.17485,644.097
163.3,6.2376,8.192,0.17483,644.908
163.6,6.2876,8.200,0.17485,645.532
163.9,6.3379,8.208,0.17483,646.143
164.2,6.3875,8.214,0.17482,646.647
164.5,6.4375,8.221,0.17482,647.180
164.8,6.4876,8.229,0.17482,647.829
165.1,6.5379,8.237,0.17482,648.433
165.4,6.5873,8.243,0.17482,648.925
165.7,6.6376,8.251,0.17485,649.527
166.0,6.6874,8.258,0.17484,650.087
166.3,6.7375,8.265,0.17485,650.638
166.6,6.7875,8.274,0.17486,651.346
166.9,6.8375,8.279,0.17485,651.755
167.2,6.8875,8.288,0.17484,652.502
167.5,6.9374,8.293,0.17485,652.885
167.8,6.9876,8.301,0.17482,653.513
168.1,7.0377,8.309,0.17481,654.170
168.4,7.0873,8.311,0.17482,654.321
168.7,7.1375,8.325,0.17482,655.416
169.0,7.1874,8.325,0.17484,655.400
169.3,7.2375,8.339,0.17487,656.514
169.6,7.2874,8.344,0.17487,656.852
169.9,7.3376,8.353,0.17484,657.613
170.2,7.3875,8.357,0.17485,657.909
170.5,7.4376,8.366,0.17484,658.648
170.8,7.4875,8.371,0.17483,658.983
171.1,7.5376,8.379,0.17483,659.675
171.4,7.5875,8.387,0.17483,660.273
171.7,7.6374,8.392,0.17482,660.677
172.0,7.6873,8.399,0.17482,661.218
172.3,7.7376,8.407,0.17484,661.878
172.6,7.7873,8.413,0.17483,662.344
172.9,7.8373,8.419,0.17484,662.772
173.2,7.8872,8.426,0.17486,663.373
173.5,7.9374,8.431,0.17486,663.748
173.8,7.9873,8.440,0.17486,664.406
174.1,8.0374,8.446,0.17487,664.949
174.4,8.0874,8.454,0.17487,665.544
174.7,8.1372,8.457,0.17485,665.796
175.0,8.1874,8.466,0.17485,666.454
175.3,8.2376,8.472,0.17484,666.986
175.6,8.2869,8.473,0.17482,667.056
175.9,8.3375,8.487,0.17484,668.174
176.2,8.3872,8.487,0.17485,668.124
176.5,8.4372,8.499,0.17485,669.084
176.8,8.4871,8.503,0.17487,669.407
177.1,8.5374,8.512,0.17488,670.116
177.4,8.5873,8.517,0.17488,670.470
177.7,8.6372,8.522,0.17487,670.882
178.0,8.6872,8.529,0.17488,671.420
178.3,8.7375,8.535,0.17485,671.938
178.6,8.7875,8.543,0.17485,672.558
178.9,8.8371,8.547,0.17485,672.845
179.2,8.8874,8.553,0.17483,673.375
179.5,8.9374,8.558,0.17483,673.772
179.8,8.9871,8.565,0.17484,674.294
180.1,9.0372,8.570,0.17486,674.681
180.4,9.0873,8.576,0.17486,675.191
180.7,9.1373,8.583,0.17488,675.728
181.0,9.1874,8.589,0.17488,676.198
181.3,9.2373,8.594,0.17488,676.567
181.6,9.2873,8.601,0.17488,677.146
181.9,9.3371,8.605,0.17487,677.429
182.2,9.3873,8.612,0.17485,677.985
182.5,9.4376,8.618,0.17484,678.456
182.8,9.4871,8.620,0.17485,678.624
183.1,9.5375,8.631,0.17485,679.495
183.4,9.5871,8.632,0.17486,679.570
183.7,9.6372,8.642,0.17488,680.380
184.0,9.6873,8.646,0.17489,680.691
184.3,9.7375,8.653,0.17488,681.210
184.6,9.7872,8.658,0.17489,681.615
184.9,9.8373,8.663,0.17487,681.999
185.2,9.8875,8.669,0.17486,682.455
185.5,9.9375,8.673,0.17485,682.821
185.8,9.9875,8.681,0.17486,683.409
186.1,10.0372,8.685,0.17484,683.731
186.4,10.0874,8.691,0.17486,684.215
186.7,10.1375,8.695,0.17487,684.532
187.0,10.1873,8.702,0.17486,685.068
187.3,10.2371,8.705,0.17488,685.341
187.6,10.2875,8.714,0.17489,686.019
187.9,10.3375,8.718,0.17489,686.334
188.2,10.3875,8.724,0.17489,686.809
188.5,10.4373,8.726,0.17489,686.992
188.8,10.4875,8.735,0.17487,687.634
189.1,10.5370,8.737,0.17485,687.833
189.4,10.5873,8.744,0.17485,688.366
189.7,10.6377,8.750,0.17487,688.849
190.0,10.6871,8.753,0.17485,689.055
190.3,10.7376,8.762,0.17489,689.831
190.6,10.7871,8.763,0.17489,689.838
190.9,10.8373,8.771,0.17490,690.498
191.2,10.8872,8.774,0.17488,690.760
191.5,10.9375,8.781,0.17488,691.291
191.8,10.9874,8.786,0.17486,691.682
192.1,11.0373,8.788,0.17486,691.876
192.4,11.0875,8.795,0.17486,692.424
192.7,11.1375,8.801,0.17485,692.836
193.0,11.1875,8.806,0.17486,693.275
193.3,11.2371,8.810,0.17487,693.584
193.6,11.2874,8.816,0.17489,694.024
193.9,11.3375,8.821,0.17488,694.412
194.2,11.3872,8.825,0.17490,694.764
194.5,11.4372,8.829,0.17489,695.065
194.8,11.4875,8.836,0.17489,695.614
195.1,11.5374,8.840,0.17488,695.912
195.4,11.5874,8.845,0.17488,696.329
195.7,11.6372,8.848,0.17486,696.529
196.0,11.6874,8.855,0.17485,697.130
196.3,11.7370,8.857,0.17486,697.276
196.6,11.7874,8.863,0.17486,697.741
196.9,11.8376,8.868,0.17487,698.120
197.2,11.8869,8.871,0.17488,698.380
197.5,11.9376,8.880,0.17489,699.092
197.8,11.9870,8.880,0.17490,699.083
198.1,12.0373,8.886,0.17491,699.579
198.4,12.0872,8.891,0.17488,699.975
198.7,12.1376,8.896,0.17487,700.337
199.0,12.1874,8.900,0.17487,700.668
199.3,12.2372,8.904,0.17487,700.965
199.6,12.2875,8.910,0.17485,701.448
199.9,12.3375,8.912,0.17486,701.615
200.2,12.3875,8.918,0.17486,702.072
200.5,12.4372,8.923,0.17486,702.470
200.8,12.4874,8.927,0.17489,702.751
201.1,12.5375,8.932,0.17489,703.180
201.4,12.5872,8.936,0.17489,703.512
201.7,12.6374,8.941,0.17490,703.882
202.0,12.6875,8.946,0.17491,704.320
202.3,12.7374,8.950,0.17489,704.571
202.6,12.7873,8.953,0.17490,704.856
202.9,12.8372,8.957,0.17489,705.153
203.2,12.8874,8.963,0.17486,705.631
203.5,12.9371,8.965,0.17487,705.792
203.8,12.9873,8.970,0.17486,706.172
204.1,13.0378,8.976,0.17487,706.674
204.4,13.0870,8.977,0.17487,706.748
204.7,13.1379,8.986,0.17490,707.449
205.0,13.1867,8.983,0.17490,707.165
205.3,13.2374,8.993,0.17491,707.950
205.6,13.2872,8.994,0.17491,708.078
205.9,13.3375,9.000,0.17490,708.532
206.2,13.3873,9.003,0.17488,708.770
206.5,13.4375,9.007,0.17488,709.112
206.8,13.4873,9.011,0.17486,709.409
207.1,13.5371,9.014,0.17487,709.606
207.4,13.5875,9.019,0.17487,710.042
207.7,13.6371,9.024,0.17488,710.421
208.0,13.6872,9.028,0.17489,710.741
208.3,13.7374,9.032,0.17490,711.056
208.6,13.7872,9.035,0.17491,711.300
208.9,13.8373,9.041,0.17491,711.794
209.2,13.8875,9.045,0.17493,712.074
209.5,13.9372,9.047,0.17491,712.245
209.8,13.9873,9.051,0.17489,712.539
210.1,14.0371,9.054,0.17488,712.786
210.4,14.0874,9.059,0.17488,713.210
210.7,14.1370,9.063,0.17486,713.491
211.0,14.1872,9.066,0.17487,713.740
211.3,14.2378,9.071,0.17488,714.128
211.6,14.2868,9.072,0.17489,714.195
211.9,14.3377,9.081,0.17491,714.885
212.2,14.3868,9.078,0.17492,714.694
212.5,14.4372,9.085,0.17492,715.198
212.8,14.4870,9.088,0.17491,715.420
213.1,14.5374,9.092,0.17491,715.780
213.4,14.5872,9.096,0.17488,716.080
213.7,14.6373,9.099,0.17488,716.348
214.0,14.6872,9.103,0.17487,716.621
214.3,14.7371,9.103,0.17487,716.631
214.6,14.7872,9.109,0.17487,717.128
214.9,14.8372,9.113,0.17488,717.462
215.2,14.8873,9.117,0.17490,717.741
215.5,14.9373,9.120,0.17489,717.944
215.8,14.9872,9.124,0.17492,718.299
216.1,15.0373,9.128,0.17491,718.647
216.4,15.0875,9.133,0.17491,718.983
216.7,15.1372,9.134,0.17491,719.110
217.0,15.1873,9.138,0.17490,719.400
217.3,15.2371,9.139,0.17486,719.500
217.6,15.2875,9.146,0.17487,720.024
217.9,15.3371,9.149,0.17488,720.269
218.2,15.3873,9.152,0.17489,720.467
218.5,15.4376,9.156,0.17490,720.796
218.8,15.4868,9.157,0.17493,720.906
219.1,15.5378,9.165,0.17492,721.528
219.4,15.5868,9.161,0.17491,721.230
219.7,15.6371,9.168,0.17491,721.767
220.0,15.6872,9.171,0.17489,722.033
220.3,15.7372,9.174,0.17488,722.228
220.6,15.7872,9.179,0.17488,722.625
220.9,15.8372,9.181,0.17487,722.807
221.2,15.8872,9.185,0.17487,723.094
221.5,15.9370,9.185,0.17489,723.134
221.8,15.9872,9.191,0.17489,723.556
222.1,16.0372,9.195,0.17489,723.901
222.4,16.0873,9.199,0.17491,724.207
222.7,16.1373,9.201,0.17491,724.345
223.0,16.1872,9.206,0.17492,724.728
223.3,16.2372,9.208,0.17493,724.925
223.6,16.2875,9.212,0.17493,725.250
223.9,16.3373,9.214,0.17491,725.384
224.2,16.3874,9.217,0.17491,725.648
224.5,16.4372,9.219,0.17489,725.760
224.8,16.4876,9.224,0.17488,726.180
225.1,16.5372,9.227,0.17488,726.391
225.4,16.5872,9.229,0.17488,726.544
225.7,16.6377,9.233,0.17488,726.910
226.0,16.6870,9.235,0.17491,727.034
226.3,16.7378,9.241,0.17493,727.477
226.6,16.7869,9.240,0.17493,727.417
226.9,16.8372,9.244,0.17493,727.739
227.2,16.8871,9.248,0.17491,728.021
227.5,16.9372,9.249,0.17489,728.140
227.8,16.9872,9.254,0.17488,728.505
228.1,17.0371,9.255,0.17488,728.574
228.4,17.0873,9.259,0.17487,728.923
228.7,17.1371,9.259,0.17489,728.934
229.0,17.1871,9.264,0.17489,729.276
229.3,17.2371,9.268,0.17491,729.635
229.6,17.2873,9.271,0.17491,729.872
229.9,17.3372,9.273,0.17494,730.022
230.2,17.3874,9.278,0.17493,730.405
230.5,17.4372,9.279,0.17493,730.482
230.8,17.4875,9.281,0.17492,730.691
231.1,17.5372,9.284,0.17490,730.903
231.4,17.5874,9.287,0.17488,731.159
231.7,17.6372,9.289,0.17488,731.268
232.0,17.6875,9.293,0.17487,731.563
232.3,17.7371,9.296,0.17488,731.829
232.6,17.7874,9.298,0.17490,731.979
232.9,17.8376,9.300,0.17490,732.114
233.2,17.8869,9.302,0.17491,732.338
233.5,17.9379,9.308,0.17493,732.741
233.8,17.9870,9.308,0.17494,732.791
234.1,18.0371,9.311,0.17492,733.002
234.4,18.0872,9.313,0.17492,733.205
234.7,18.1372,9.315,0.17489,733.347
235.0,18.1872,9.319,0.17488,733.619
235.3,18.2372,9.319,0.17488,733.673
235.6,18.2874,9.324,0.17488,734.019
235.9,18.3371,9.324,0.17488,734.051
236.2,18.3871,9.327,0.17488,734.291
236.5,18.4371,9.330,0.17490,734.547
236.8,18.4873,9.334,0.17490,734.787
237.1,18.5372,9.335,0.17493,734.874
237.4,18.5874,9.339,0.17494,735.196
237.7,18.6371,9.339,0.17493,735.237
238.0,18.6874,9.342,0.17493,735.473
238.3,18.7374,9.345,0.17492,735.697
238.6,18.7874,9.347,0.17489,735.824
238.9,18.8371,9.348,0.17488,735.928
239.2,18.8874,9.351,0.17489,736.197
239.5,18.9372,9.355,0.17488,736.470
239.8,18.9872,9.356,0.17490,736.574
240.1,19.0375,9.359,0.17490,736.791
240.4,19.0871,9.361,0.17492,736.985
240.7,19.1379,9.366,0.17492,737.333
241.0,19.1870,9.365,0.17494,737.239
241.3,19.2372,9.368,0.17491,737.510
241.6,19.2871,9.370,0.17490,737.623
241.9,19.3373,9.373,0.17490,737.865
242.2,19.3872,9.375,0.17488,738.082
242.5,19.4373,9.376,0.17489,738.156
242.8,19.4873,9.380,0.17489,738.408
243.1,19.5372,9.381,0.17489,738.559
243.4,19.5871,9.382,0.17490,738.592
243.7,19.6371,9.386,0.17494,738.918
244.0,19.6872,9.388,0.17493,739.050
244.3,19.7371,9.389,0.17494,739.167
244.6,19.7871,9.392,0.17493,739.421
244.9,19.8371,9.394,0.17493,739.513
245.2,19.8873,9.396,0.17491,739.692
245.5,19.9372,9.397,0.17492,739.803
245.8,19.9871,9.399,0.17489,739.942
246.1,20.0371,9.402,0.17489,740.208
246.4,20.0872,9.402,0.17490,740.198
246.7,20.1370,9.407,0.17491,740.568
247.0,20.1872,9.408,0.17490,740.651
247.3,20.2376,9.410,0.17493,740.783
247.6,20.2870,9.412,0.17495,740.966
247.9,20.3377,9.415,0.17494,741.224
248.2,20.3869,9.415,0.17494,741.186
248.5,20.4371,9.417,0.17491,741.367
248.8,20.4871,9.419,0.17490,741.511
249.1,20.5372,9.421,0.17489,741.642
249.4,20.5872,9.423,0.17490,741.818
249.7,20.6372,9.425,0.17489,741.986
250.0,20.6874,9.427,0.17492,742.115
250.3,20.7371,9.429,0.17493,742.277
250.6,20.7870,9.429,0.17494,742.302
250.9,20.8371,9.432,0.17495,742.579
251.2,20.8871,9.434,0.17495,742.675
251.5,20.9370,9.435,0.17493,742.769
251.8,20.9872,9.438,0.17492,743.027
252.1,21.0371,9.438,0.17491,743.032
252.4,21.0872,9.440,0.17489,743.203
252.7,21.1371,9.442,0.17490,743.330
253.0,21.1872,9.444,0.17492,743.466
253.3,21.2370,9.445,0.17493,743.560
253.6,21.2871,9.447,0.17493,743.717
253.9,21.3372,9.451,0.17494,744.037
254.2,21.3873,9.451,0.17493,744.072
254.5,21.4375,9.453,0.17495,744.177
254.8,21.4870,9.455,0.17493,744.320
255.1,21.5378,9.457,0.17491,744.516
255.4,21.5869,9.457,0.17489,744.521
255.7,21.6372,9.459,0.17490,744.687
256.0,21.6872,9.461,0.17490,744.801
256.3,21.7372,9.461,0.17491,744.824
256.6,21.7873,9.464,0.17493,745.071
256.9,21.8372,9.465,0.17494,745.143
257.2,21.8875,9.467,0.17495,745.328
257.5,21.9372,9.468,0.17495,745.346
257.8,21.9871,9.467,0.17494,745.295
258.1,22.0371,9.470,0.17492,745.525
258.4,22.0873,9.472,0.17493,745.705
258.7,22.1370,9.471,0.17490,745.611
259.0,22.1873,9.475,0.17489,745.952
259.3,22.2370,9.475,0.17490,745.919
259.6,22.2872,9.478,0.17490,746.155
259.9,22.3371,9.478,0.17490,746.180
260.2,22.3872,9.482,0.17491,746.495
260.5,22.4368,9.481,0.17493,746.418
260.8,22.4871,9.483,0.17492,746.525
261.1,22.5371,9.485,0.17494,746.745
261.4,22.5874,9.489,0.17496,747.022
261.7,22.6375,9.487,0.17495,746.857
262.0,22.6871,9.490,0.17494,747.140
262.3,22.7376,9.491,0.17494,747.165
262.6,22.7871,9.493,0.17491,747.313
262.9,22.8372,9.493,0.17490,747.343
263.2,22.8871,9.495,0.17490,747.497
263.5,22.9371,9.496,0.17490,747.553
263.8,22.9872,9.498,0.17490,747.733
264.1,23.0372,9.499,0.17493,747.838
264.4,23.0875,9.501,0.17495,747.952
264.7,23.1371,9.502,0.17495,748.015
265.0,23.1869,9.502,0.17496,748.051
265.3,23.2371,9.504,0.17494,748.211
265.6,23.2874,9.506,0.17494,748.373
265.9,23.3371,9.505,0.17493,748.272
266.2,23.3871,9.508,0.17490,748.505
266.5,23.4371,9.508,0.17490,748.554
266.8,23.4872,9.509,0.17490,748.625
267.1,23.5370,9.510,0.17491,748.701
267.4,23.5873,9.514,0.17491,748.973
267.7,23.6370,9.513,0.17492,748.935
268.0,23.6870,9.514,0.17494,749.018
268.3,23.7371,9.517,0.17494,749.244
268.6,23.7874,9.519,0.17495,749.406
268.9,23.8372,9.516,0.17496,749.167
269.2,23.8871,9.520,0.17492,749.491
269.5,23.9374,9.519,0.17492,749.362
269.8,23.9870,9.522,0.17491,749.602
270.1,24.0371,9.522,0.17490,749.597
270.4,24.0871,9.524,0.17489,749.767
270.7,24.1370,9.523,0.17492,749.686
271.0,24.1872,9.525,0.17492,749.867
271.3,24.2372,9.526,0.17492,749.933
271.6,24.2872,9.527,0.17495,749.989
271.9,24.3370,9.528,0.17495,750.106
272.2,24.3870,9.528,0.17495,750.071
272.5,24.4371,9.530,0.17495,750.292
272.8,24.4873,9.531,0.17494,750.337
273.1,24.5370,9.530,0.17492,750.251
273.4,24.5872,9.532,0.17493,750.388
273.7,24.6371,9.533,0.17491,750.473
274.0,24.6871,9.532,0.17490,750.442
274.3,24.7372,9.535,0.17490,750.627
274.6,24.7872,9.535,0.17490,750.637
274.9,24.8371,9.536,0.17491,750.750
275.2,24.8870,9.536,0.17493,750.702
275.5,24.9371,9.538,0.17495,750.902
275.8,24.9873,9.539,0.17495,750.971
276.1,25.0371,9.536,0.17495,750.744
276.4,25.0871,9.541,0.17493,751.092
276.7,25.1372,9.537,0.17491,750.794
277.0,25.1871,9.543,0.17490,751.252
277.3,25.2370,9.541,0.17490,751.130
277.6,25.2871,9.543,0.17490,751.289
277.9,25.3370,9.541,0.17494,751.159
278.2,25.3871,9.544,0.17495,751.345
278.5,25.4371,9.544,0.17496,751.337
278.8,25.4872,9.545,0.17496,751.446
279.1,25.5371,9.545,0.17495,751.467
279.4,25.5870,9.544,0.17492,751.357
279.7,25.6371,9.546,0.17491,751.494
280.0,25.6873,9.547,0.17491,751.565
280.3,25.7371,9.546,0.17490,751.485
280.6,25.7871,9.546,0.17490,751.535
280.9,25.8370,9.548,0.17491,751.658
281.2,25.8871,9.546,0.17492,751.520
281.5,25.9371,9.548,0.17491,751.643
281.8,25.9871,9.548,0.17493,751.640
282.1,26.0372,9.550,0.17494,751.804
282.4,26.0869,9.546,0.17495,751.551
282.7,26.1372,9.550,0.17496,751.830
283.0,26.1873,9.549,0.17494,751.758
283.3,26.2369,9.546,0.17493,751.523
283.6,26.2870,9.551,0.17492,751.878
283.9,26.3372,9.546,0.17492,751.517
284.2,26.3870,9.551,0.17490,751.892
284.5,26.4371,9.550,0.17491,751.850
284.8,26.4872,9.551,0.17492,751.905
285.1,26.5371,9.549,0.17494,751.784
285.4,26.5871,9.550,0.17495,751.864
285.7,26.6372,9.551,0.17497,751.900
286.0,26.6873,9.550,0.17496,751.836
286.3,26.7373,9.551,0.17495,751.911
286.6,26.7869,9.549,0.17494,751.743
286.9,26.8372,9.550,0.17493,751.859
287.2,26.8874,9.550,0.17492,751.792
287.5,26.9370,9.547,0.17492,751.634
287.8,26.9871,9.547,0.17489,751.591
288.1,27.0371,9.548,0.17489,751.672
288.4,27.0871,9.546,0.17493,751.492
288.7,27.1371,9.548,0.17493,751.653
289.0,27.1871,9.546,0.17495,751.502
289.3,27.2372,9.548,0.17495,751.691
289.6,27.2869,9.544,0.17496,751.338
289.9,27.3372,9.546,0.17494,751.542
290.2,27.3873,9.544,0.17495,751.347
290.5,27.4367,9.540,0.17494,751.016
290.8,27.4871,9.544,0.17491,751.362
291.1,27.5371,9.539,0.17490,751.000
291.4,27.5871,9.543,0.17491,751.253
291.7,27.6371,9.539,0.17491,750.995
292.0,27.6872,9.540,0.17492,751.049
292.3,27.7371,9.538,0.17494,750.875
292.6,27.7871,9.538,0.17494,750.876
292.9,27.8373,9.536,0.17496,750.738
293.2,27.8873,9.535,0.17496,750.650
293.5,27.9373,9.535,0.17495,750.625
293.8,27.9871,9.531,0.17494,750.323
294.1,28.0371,9.530,0.17495,750.254
294.4,28.0872,9.528,0.17493,750.071
294.7,28.1371,9.526,0.17491,749.941
295.0,28.1870,9.522,0.17492,749.633
295.3,28.2370,9.521,0.17491,749.561
295.6,28.2871,9.518,0.17490,749.304
295.9,28.3371,9.516,0.17491,749.135
296.2,28.3871,9.513,0.17494,748.881
296.5,28.4371,9.512,0.17495,748.840
296.8,28.4868,9.505,0.17497,748.285
297.1,28.5370,9.503,0.17497,748.145
297.4,28.5875,9.501,0.17496,747.963
297.7,28.6368,9.491,0.17495,747.192
298.0,28.6874,9.493,0.17494,747.367
298.3,28.7371,9.482,0.17491,746.493
298.6,28.7871,9.483,0.17490,746.550
298.9,28.8371,9.475,0.17492,745.965
299.2,28.8873,9.470,0.17492,745.572
299.5,28.9371,9.463,0.17494,745.019
299.8,28.9872,9.458,0.17496,744.569
300.1,29.0372,9.449,0.17497,743.904
300.4,29.0875,9.443,0.17495,743.425
300.7,29.1373,9.435,0.17496,742.752
301.0,29.1869,9.425,0.17493,741.976
301.3,29.2371,9.415,0.17492,741.185
301.6,29.2874,9.405,0.17492,740.431
301.9,29.3369,9.394,0.17491,739.519
302.2,29.3870,9.381,0.17490,738.537
302.5,29.4371,9.368,0.17492,737.541
302.8,29.4872,9.354,0.17493,736.435
303.1,29.5371,9.339,0.17494,735.238
303.4,29.5871,9.322,0.17495,733.910
303.7,29.6371,9.306,0.17497,732.658
304.0,29.6868,9.285,0.17496,730.958
304.3,29.7371,9.265,0.17495,729.413
304.6,29.7875,9.243,0.17496,727.696
304.9,29.8370,9.216,0.17492,725.545
305.2,29.8875,9.194,0.17492,723.829
305.5,29.9371,9.157,0.17491,720.899
305.8,29.9872,9.128,0.17490,718.608
306.1,30.0371,9.086,0.17491,715.301
306.4,30.0875,9.039,0.17494,711.632
306.7,30.1372,8.976,0.17495,706.648
307.0,30.1872,8.894,0.17495,700.205
307.3,30.2375,8.775,0.17497,690.806
307.6,30.2877,8.607,0.17496,677.554
307.9,30.3376,8.353,0.17496,657.611
308.2,30.3876,7.840,0.17493,617.233
308.3,30.3996,-0.393,0.17586,-30.923