File: LAB 1 - Deformation (tensile test)/FDcurve_specimen2.txt
Time(s),Crosshead(mm),Load(kN),Extensometer(mm/mm),Stress(MPa)
1.2,0.0015,0.227,0.00000,19.7
1.4,0.0046,0.260,0.00002,22.7
1.6,0.0079,0.296,0.00003,25.7
1.8,0.0112,0.327,0.00005,28.5
2.0,0.0145,0.356,0.00006,31.0
2.2,0.0177,0.381,0.00007,33.1
2.4,0.0212,0.404,0.00008,35.2
2.6,0.0244,0.424,0.00009,36.9
2.8,0.0277,0.445,0.00010,38.7
3.0,0.0309,0.462,0.00011,40.2
3.2,0.0344,0.480,0.00011,41.8
3.4,0.0376,0.496,0.00012,43.2
3.6,0.0412,0.513,0.00013,44.7
3.8,0.0444,0.528,0.00013,46.0
4.0,0.0479,0.543,0.00014,47.3
4.2,0.0512,0.560,0.00015,48.8
4.4,0.0545,0.578,0.00016,50.3
4.6,0.0579,0.595,0.00017,51.8
4.8,0.0612,0.614,0.00017,53.4
5.0,0.0646,0.632,0.00018,55.0
5.2,0.0679,0.650,0.00019,56.6
5.4,0.0712,0.668,0.00019,58.2
5.6,0.0744,0.685,0.00020,59.6
5.8,0.0779,0.703,0.00021,61.2
6.0,0.0811,0.719,0.00022,62.6
6.2,0.0845,0.738,0.00022,64.2
6.4,0.0877,0.753,0.00023,65.6
6.6,0.0912,0.771,0.00024,67.1
6.8,0.0944,0.786,0.00025,68.4
7.0,0.0978,0.802,0.00026,69.8
7.2,0.1011,0.816,0.00026,71.1
7.4,0.1045,0.831,0.00027,72.3
7.6,0.1077,0.845,0.00028,73.6
7.8,0.1112,0.860,0.00028,74.8
8.0,0.1145,0.872,0.00029,75.9
8.2,0.1178,0.885,0.00030,77.1
8.4,0.1212,0.898,0.00030,78.2
8.6,0.1245,0.911,0.00030,79.3
8.8,0.1279,0.924,0.00031,80.4
9.0,0.1311,0.935,0.00031,81.4
9.2,0.1345,0.946,0.00031,82.4
9.4,0.1377,0.955,0.00032,83.2
9.6,0.1411,0.967,0.00033,84.2
9.8,0.1444,0.976,0.00033,85.0
10.0,0.1477,0.987,0.00034,86.0
10.2,0.1510,0.996,0.00034,86.7
10.4,0.1544,1.007,0.00034,87.6
10.6,0.1576,1.016,0.00035,88.4
10.8,0.1610,1.027,0.00036,89.4
11.0,0.1642,1.036,0.00036,90.2
11.2,0.1676,1.047,0.00036,91.1
11.4,0.1709,1.056,0.00036,91.9
11.6,0.1743,1.065,0.00037,92.7
11.8,0.1776,1.075,0.00038,93.6
12.0,0.1810,1.084,0.00038,94.4
12.2,0.1844,1.094,0.00039,95.2
12.4,0.1877,1.103,0.00039,96.0
12.6,0.1911,1.112,0.00039,96.8
12.8,0.1944,1.121,0.00039,97.6
13.0,0.1978,1.130,0.00039,98.4
13.2,0.2011,1.138,0.00040,99.1
13.4,0.2045,1.147,0.00040,99.9
13.6,0.2077,1.156,0.00041,100.6
13.8,0.2112,1.167,0.00041,101.6
14.0,0.2145,1.174,0.00042,102.2
14.2,0.2179,1.185,0.00043,103.2
14.4,0.2211,1.193,0.00043,103.9
14.6,0.2244,1.204,0.00043,104.8
14.8,0.2276,1.213,0.00043,105.6
15.0,0.2309,1.225,0.00044,106.6
15.2,0.2342,1.235,0.00045,107.5
15.4,0.2376,1.246,0.00045,108.5
15.6,0.2408,1.256,0.00045,109.4
15.8,0.2442,1.267,0.00046,110.3
16.0,0.2474,1.277,0.00046,111.2
16.2,0.2508,1.288,0.00047,112.1
16.4,0.2542,1.297,0.00047,112.9
16.6,0.2576,1.307,0.00047,113.8
16.8,0.2609,1.318,0.00048,114.7
17.0,0.2643,1.327,0.00048,115.5
17.2,0.2676,1.337,0.00048,116.4
17.4,0.2709,1.345,0.00049,117.1
17.6,0.2744,1.356,0.00049,118.1
17.8,0.2776,1.364,0.00049,118.7
18.0,0.2811,1.373,0.00050,119.5
18.2,0.2843,1.381,0.00050,120.2
18.4,0.2877,1.390,0.00050,121.0
18.6,0.2909,1.397,0.00051,121.6
18.8,0.2943,1.407,0.00051,122.5
19.0,0.2976,1.414,0.00052,123.1
19.2,0.3009,1.423,0.00052,123.9
19.4,0.3043,1.431,0.00052,124.5
19.6,0.3076,1.438,0.00053,125.2
19.8,0.3110,1.446,0.00053,125.9
20.0,0.3144,1.453,0.00053,126.5
20.2,0.3177,1.461,0.00053,127.2
20.4,0.3211,1.468,0.00053,127.8
20.6,0.3245,1.475,0.00053,128.4
20.8,0.3277,1.481,0.00054,129.0
21.0,0.3312,1.489,0.00055,129.6
21.2,0.3344,1.495,0.00054,130.1
21.4,0.3379,1.503,0.00055,130.8
21.6,0.3411,1.508,0.00055,131.3
21.8,0.3445,1.516,0.00055,132.0
22.0,0.3478,1.521,0.00056,132.5
22.2,0.3513,1.528,0.00056,133.1
22.4,0.3545,1.534,0.00056,133.6
22.6,0.3580,1.541,0.00056,134.1
22.8,0.3612,1.546,0.00056,134.6
23.0,0.3645,1.551,0.00057,135.1
23.2,0.3679,1.557,0.00057,135.6
23.4,0.3712,1.562,0.00057,136.0
23.6,0.3745,1.569,0.00057,136.6
23.8,0.3778,1.574,0.00057,137.0
24.0,0.3811,1.580,0.00058,137.5
24.2,0.3843,1.584,0.00058,137.9
24.4,0.3876,1.590,0.00058,138.5
24.6,0.3908,1.595,0.00058,138.8
24.8,0.3941,1.602,0.00058,139.5
25.0,0.3973,1.606,0.00059,139.8
25.2,0.4007,1.611,0.00059,140.3
25.4,0.4040,1.615,0.00059,140.6
25.6,0.4073,1.620,0.00059,141.1
25.8,0.4107,1.625,0.00060,141.4
26.0,0.4141,1.630,0.00060,141.9
26.2,0.4173,1.634,0.00060,142.2
26.4,0.4208,1.640,0.00060,142.8
26.6,0.4240,1.644,0.00060,143.1
26.8,0.4275,1.650,0.00060,143.6
27.0,0.4308,1.654,0.00061,144.0
27.2,0.4341,1.658,0.00061,144.4
27.4,0.4376,1.664,0.00062,144.9
27.6,0.4409,1.668,0.00061,145.2
27.8,0.4444,1.673,0.00062,145.7
28.0,0.4478,1.678,0.00062,146.1
28.2,0.4512,1.683,0.00062,146.5
28.4,0.4545,1.687,0.00062,146.9
28.6,0.4580,1.693,0.00062,147.3
28.8,0.4612,1.695,0.00063,147.6
29.0,0.4647,1.701,0.00062,148.1
29.2,0.4679,1.703,0.00063,148.3
29.4,0.4713,1.708,0.00062,148.7
29.6,0.4745,1.711,0.00063,148.9
29.8,0.4780,1.715,0.00063,149.3
30.0,0.4811,1.718,0.00062,149.6
30.2,0.4844,1.722,0.00063,149.9
30.4,0.4876,1.725,0.00063,150.2
30.6,0.4909,1.730,0.00063,150.6
30.8,0.4941,1.733,0.00064,150.9
31.0,0.4975,1.739,0.00064,151.4
31.2,0.5006,1.744,0.00064,151.8
31.4,0.5040,1.751,0.00064,152.5
31.6,0.5072,1.758,0.00064,153.1
31.8,0.5107,1.767,0.00065,153.8
32.0,0.5141,1.777,0.00065,154.7
32.2,0.5174,1.786,0.00066,155.5
32.4,0.5208,1.797,0.00066,156.4
32.6,0.5241,1.806,0.00067,157.2
32.8,0.5275,1.817,0.00067,158.2
33.0,0.5308,1.826,0.00067,158.9
33.2,0.5342,1.836,0.00067,159.8
33.4,0.5375,1.844,0.00068,160.6
33.6,0.5409,1.854,0.00068,161.4
33.8,0.5441,1.862,0.00068,162.1
34.0,0.5476,1.872,0.00069,163.0
34.2,0.5508,1.880,0.00069,163.7
34.4,0.5542,1.890,0.00069,164.6
34.6,0.5575,1.900,0.00070,165.4
34.8,0.5608,1.908,0.00070,166.1
35.0,0.5641,1.918,0.00070,167.0
35.2,0.5675,1.927,0.00071,167.8
35.4,0.5709,1.938,0.00071,168.7
35.6,0.5742,1.947,0.00071,169.5
35.8,0.5776,1.958,0.00072,170.4
36.0,0.5808,1.966,0.00072,171.2
36.2,0.5843,1.978,0.00073,172.2
36.4,0.5874,1.986,0.00073,172.9
36.6,0.5908,1.997,0.00073,173.8
36.8,0.5940,2.004,0.00074,174.4
37.0,0.5974,2.016,0.00074,175.5
37.2,0.6006,2.024,0.00074,176.2
37.4,0.6040,2.035,0.00075,177.2
37.6,0.6073,2.044,0.00075,177.9
37.8,0.6108,2.055,0.00075,178.9
38.0,0.6140,2.064,0.00076,179.7
38.2,0.6174,2.074,0.00076,180.6
38.4,0.6207,2.084,0.00077,181.4
38.6,0.6240,2.094,0.00077,182.3
38.8,0.6274,2.104,0.00077,183.2
39.0,0.6307,2.114,0.00078,184.0
39.2,0.6341,2.125,0.00078,185.0
39.4,0.6375,2.135,0.00079,185.9
39.6,0.6409,2.147,0.00079,186.9
39.8,0.6442,2.156,0.00080,187.7
40.0,0.6476,2.167,0.00080,188.6
40.2,0.6509,2.177,0.00081,189.5
40.4,0.6543,2.188,0.00080,190.5
40.6,0.6575,2.197,0.00081,191.3
40.8,0.6609,2.209,0.00082,192.3
41.0,0.6641,2.218,0.00081,193.1
41.2,0.6676,2.230,0.00082,194.1
41.4,0.6708,2.239,0.00083,195.0
41.6,0.6741,2.251,0.00083,196.0
41.8,0.6774,2.261,0.00084,196.9
42.0,0.6808,2.272,0.00084,197.8
42.2,0.6840,2.283,0.00084,198.8
42.4,0.6874,2.294,0.00084,199.7
42.6,0.6908,2.305,0.00085,200.6
42.8,0.6940,2.315,0.00085,201.6
43.0,0.6974,2.327,0.00086,202.5
43.2,0.7007,2.337,0.00086,203.5
43.4,0.7042,2.349,0.00087,204.5
43.6,0.7074,2.359,0.00087,205.3
43.8,0.7109,2.371,0.00087,206.4
44.0,0.7141,2.379,0.00088,207.1
44.2,0.7176,2.391,0.00088,208.2
44.4,0.7208,2.400,0.00089,209.0
44.6,0.7242,2.412,0.00089,210.0
44.8,0.7274,2.422,0.00089,210.8
45.0,0.7308,2.434,0.00090,211.9
45.2,0.7341,2.444,0.00090,212.8
45.4,0.7375,2.455,0.00091,213.7
45.6,0.7408,2.465,0.00091,214.6
45.8,0.7441,2.476,0.00091,215.6
46.0,0.7475,2.488,0.00092,216.6
46.2,0.7508,2.499,0.00093,217.5
46.4,0.7541,2.511,0.00093,218.6
46.6,0.7574,2.521,0.00093,219.5
46.8,0.7608,2.533,0.00094,220.6
47.0,0.7640,2.543,0.00094,221.4
47.2,0.7673,2.556,0.00094,222.5
47.4,0.7707,2.566,0.00095,223.4
47.6,0.7741,2.578,0.00095,224.5
47.8,0.7773,2.588,0.00096,225.3
48.0,0.7808,2.600,0.00097,226.4
48.2,0.7840,2.611,0.00096,227.3
48.4,0.7874,2.623,0.00097,228.3
48.6,0.7907,2.633,0.00098,229.2
48.8,0.7940,2.645,0.00098,230.3
49.0,0.7973,2.656,0.00099,231.2
49.2,0.8007,2.667,0.00099,232.2
49.4,0.8040,2.678,0.00099,233.2
49.6,0.8073,2.690,0.00100,234.2
49.8,0.8107,2.702,0.00100,235.2
50.0,0.8140,2.713,0.00100,236.2
50.2,0.8175,2.726,0.00101,237.3
50.4,0.8208,2.737,0.00102,238.2
50.6,0.8241,2.749,0.00102,239.4
50.8,0.8274,2.760,0.00102,240.2
51.0,0.8308,2.772,0.00103,241.4
51.2,0.8341,2.782,0.00103,242.2
51.4,0.8376,2.796,0.00103,243.4
51.6,0.8408,2.806,0.00104,244.3
51.8,0.8442,2.819,0.00105,245.4
52.0,0.8474,2.829,0.00105,246.3
52.2,0.8507,2.842,0.00105,247.4
52.4,0.8539,2.853,0.00106,248.4
52.6,0.8572,2.865,0.00106,249.4
52.8,0.8604,2.877,0.00106,250.5
53.0,0.8638,2.889,0.00108,251.5
53.2,0.8672,2.902,0.00108,252.6
53.4,0.8705,2.913,0.00108,253.6
53.6,0.8740,2.926,0.00108,254.7
53.8,0.8772,2.937,0.00110,255.7
54.0,0.8807,2.950,0.00110,256.9
54.2,0.8840,2.961,0.00110,257.8
54.4,0.8874,2.974,0.00111,258.9
54.6,0.8906,2.985,0.00112,259.9
54.8,0.8940,2.998,0.00112,261.0
55.0,0.8972,3.009,0.00112,261.9
55.2,0.9007,3.023,0.00113,263.2
55.4,0.9039,3.034,0.00113,264.1
55.6,0.9073,3.047,0.00113,265.3
55.8,0.9105,3.059,0.00114,266.3
56.0,0.9139,3.072,0.00115,267.5
56.2,0.9171,3.084,0.00115,268.5
56.4,0.9204,3.097,0.00116,269.6
56.6,0.9237,3.109,0.00116,270.7
56.8,0.9270,3.121,0.00117,271.7
57.0,0.9304,3.134,0.00117,272.9
57.2,0.9337,3.147,0.00117,274.0
57.4,0.9372,3.161,0.00118,275.2
57.6,0.9404,3.172,0.00118,276.2
57.8,0.9437,3.187,0.00119,277.4
58.0,0.9471,3.199,0.00119,278.5
58.2,0.9504,3.212,0.00120,279.6
58.4,0.9536,3.223,0.00121,280.6
58.6,0.9571,3.237,0.00121,281.8
58.8,0.9603,3.249,0.00121,282.8
59.0,0.9637,3.263,0.00122,284.0
59.2,0.9669,3.275,0.00122,285.1
59.4,0.9704,3.289,0.00123,286.3
59.6,0.9737,3.302,0.00124,287.5
59.8,0.9771,3.315,0.00124,288.6
60.0,0.9804,3.328,0.00124,289.7
60.2,0.9837,3.341,0.00125,290.9
60.4,0.9871,3.354,0.00126,292.0
60.6,0.9904,3.367,0.00126,293.2
60.8,0.9938,3.382,0.00127,294.5
61.0,0.9971,3.395,0.00127,295.6
61.2,1.0005,3.409,0.00128,296.8
61.4,1.0037,3.422,0.00128,297.9
61.6,1.0072,3.436,0.00129,299.1
61.8,1.0104,3.447,0.00129,300.1
62.0,1.0139,3.462,0.00130,301.4
62.2,1.0172,3.474,0.00130,302.4
62.4,1.0205,3.488,0.00130,303.7
62.6,1.0237,3.501,0.00131,304.7
62.8,1.0272,3.516,0.00131,306.1
63.0,1.0304,3.528,0.00132,307.1
63.2,1.0339,3.542,0.00133,308.4
63.4,1.0372,3.555,0.00133,309.5
63.6,1.0405,3.570,0.00134,310.8
63.8,1.0440,3.583,0.00134,312.0
64.0,1.0472,3.597,0.00135,313.1
64.2,1.0505,3.612,0.00135,314.4
64.4,1.0538,3.624,0.00136,315.5
64.6,1.0572,3.638,0.00137,316.7
64.8,1.0604,3.651,0.00137,317.9
65.0,1.0637,3.665,0.00137,319.1
65.2,1.0669,3.679,0.00138,320.3
65.4,1.0703,3.693,0.00139,321.5
65.6,1.0735,3.706,0.00139,322.7
65.8,1.0769,3.722,0.00140,324.0
66.0,1.0802,3.735,0.00140,325.1
66.2,1.0836,3.750,0.00141,326.5
66.4,1.0868,3.762,0.00142,327.5
66.6,1.0901,3.777,0.00142,328.8
66.8,1.0935,3.790,0.00142,329.9
67.0,1.0968,3.803,0.00142,331.1
67.2,1.1002,3.819,0.00144,332.5
67.4,1.1036,3.833,0.00144,333.7
67.6,1.1072,3.848,0.00145,335.0
67.8,1.1104,3.863,0.00145,336.3
68.0,1.1139,3.877,0.00146,337.6
68.2,1.1171,3.891,0.00146,338.7
68.4,1.1204,3.906,0.00147,340.0
68.6,1.1236,3.917,0.00148,341.0
68.8,1.1270,3.934,0.00148,342.4
69.0,1.1302,3.946,0.00148,343.6
69.2,1.1336,3.962,0.00149,344.9
69.4,1.1369,3.974,0.00150,346.0
69.6,1.1403,3.989,0.00150,347.3
69.8,1.1436,4.003,0.00151,348.5
70.0,1.1470,4.020,0.00152,349.9
70.2,1.1503,4.033,0.00152,351.1
70.4,1.1537,4.049,0.00152,352.5
70.6,1.1571,4.064,0.00153,353.8
70.8,1.1604,4.078,0.00154,355.0
71.0,1.1637,4.094,0.00155,356.4
71.2,1.1670,4.109,0.00155,357.7
71.4,1.1704,4.125,0.00155,359.1
71.6,1.1737,4.139,0.00156,360.3
71.8,1.1771,4.155,0.00157,361.7
72.0,1.1804,4.168,0.00157,362.9
72.2,1.1837,4.184,0.00158,364.3
72.4,1.1870,4.198,0.00158,365.5
72.6,1.1904,4.213,0.00159,366.8
72.8,1.1936,4.227,0.00160,368.0
73.0,1.1970,4.244,0.00159,369.4
73.2,1.2003,4.257,0.00160,370.6
73.4,1.2036,4.273,0.00161,372.0
73.6,1.2069,4.287,0.00161,373.3
73.8,1.2102,4.302,0.00162,374.5
74.0,1.2135,4.318,0.00163,375.9
74.2,1.2168,4.332,0.00164,377.2
74.4,1.2201,4.348,0.00164,378.5
74.6,1.2234,4.363,0.00165,379.8
74.8,1.2268,4.379,0.00165,381.2
75.0,1.2300,4.394,0.00166,382.5
75.2,1.2335,4.411,0.00167,384.0
75.4,1.2368,4.426,0.00167,385.3
75.6,1.2403,4.444,0.00167,386.9
75.8,1.2434,4.457,0.00168,388.0
76.0,1.2469,4.474,0.00169,389.5
76.2,1.2501,4.487,0.00169,390.6
76.4,1.2536,4.504,0.00170,392.1
76.6,1.2568,4.519,0.00171,393.4
76.8,1.2602,4.535,0.00171,394.8
77.0,1.2634,4.550,0.00172,396.1
77.2,1.2668,4.566,0.00172,397.5
77.4,1.2700,4.582,0.00173,398.9
77.6,1.2735,4.599,0.00174,400.4
77.8,1.2768,4.613,0.00175,401.6
78.0,1.2801,4.630,0.00175,403.1
78.2,1.2835,4.645,0.00175,404.4
78.4,1.2868,4.661,0.00176,405.8
78.6,1.2901,4.678,0.00177,407.2
78.8,1.2935,4.693,0.00178,408.6
79.0,1.2968,4.710,0.00178,410.1
79.2,1.3001,4.726,0.00179,411.4
79.4,1.3036,4.743,0.00180,412.9
79.6,1.3069,4.758,0.00180,414.2
79.8,1.3103,4.775,0.00181,415.7
80.0,1.3135,4.790,0.00182,417.0
80.2,1.3169,4.807,0.00182,418.5
80.4,1.3201,4.822,0.00183,419.8
80.6,1.3236,4.839,0.00184,421.3
80.8,1.3268,4.854,0.00184,422.6
81.0,1.3301,4.871,0.00185,424.1
81.2,1.3334,4.886,0.00185,425.4
81.4,1.3367,4.903,0.00186,426.9
81.6,1.3400,4.919,0.00186,428.2
81.8,1.3433,4.935,0.00188,429.6
82.0,1.3466,4.952,0.00187,431.1
82.2,1.3499,4.968,0.00189,432.5
82.4,1.3532,4.984,0.00189,433.9
82.6,1.3565,5.001,0.00190,435.4
82.8,1.3599,5.018,0.00191,436.9
83.0,1.3632,5.036,0.00191,438.4
83.2,1.3666,5.053,0.00192,439.9
83.4,1.3699,5.069,0.00192,441.3
83.6,1.3733,5.087,0.00194,442.9
83.8,1.3765,5.102,0.00194,444.2
84.0,1.3800,5.122,0.00195,445.9
84.2,1.3832,5.137,0.00195,447.2
84.4,1.3867,5.154,0.00196,448.7
84.6,1.3900,5.171,0.00197,450.2
84.8,1.3934,5.189,0.00197,451.7
85.0,1.3967,5.205,0.00198,453.2
85.2,1.4000,5.224,0.00199,454.8
85.4,1.4033,5.240,0.00199,456.2
85.6,1.4068,5.258,0.00200,457.7
85.8,1.4101,5.274,0.00201,459.2
86.0,1.4133,5.292,0.00201,460.7
86.2,1.4167,5.309,0.00202,462.2
86.4,1.4200,5.326,0.00202,463.7
86.6,1.4232,5.344,0.00204,465.3
86.8,1.4265,5.360,0.00204,466.7
87.0,1.4299,5.379,0.00204,468.3
87.2,1.4331,5.395,0.00205,469.7
87.4,1.4364,5.414,0.00206,471.3
87.6,1.4397,5.430,0.00207,472.8
87.8,1.4431,5.448,0.00208,474.3
88.0,1.4464,5.465,0.00208,475.8
88.2,1.4499,5.484,0.00209,477.4
88.4,1.4532,5.501,0.00209,478.9
88.6,1.4565,5.520,0.00210,480.5
88.8,1.4599,5.536,0.00211,482.0
89.0,1.4632,5.554,0.00211,483.5
89.2,1.4664,5.572,0.00212,485.1
89.4,1.4698,5.590,0.00213,486.6
89.6,1.4732,5.608,0.00214,488.2
89.8,1.4765,5.625,0.00214,489.7
90.0,1.4800,5.644,0.00215,491.3
90.2,1.4832,5.661,0.00216,492.9
90.4,1.4865,5.680,0.00216,494.5
90.6,1.4898,5.696,0.00217,495.9
90.8,1.4932,5.715,0.00218,497.5
91.0,1.4964,5.732,0.00218,499.0
91.2,1.5000,5.751,0.00219,500.7
91.4,1.5032,5.767,0.00220,502.0
91.6,1.5066,5.786,0.00221,503.7
91.8,1.5098,5.803,0.00221,505.2
92.0,1.5133,5.822,0.00222,506.8
92.2,1.5165,5.839,0.00223,508.4
92.4,1.5200,5.859,0.00223,510.0
92.6,1.5232,5.876,0.00225,511.5
92.8,1.5265,5.894,0.00225,513.1
93.0,1.5299,5.911,0.00225,514.6
93.2,1.5332,5.930,0.00226,516.3
93.4,1.5366,5.948,0.00227,517.8
93.6,1.5400,5.967,0.00228,519.4
93.8,1.5434,5.986,0.00229,521.1
94.0,1.5467,6.004,0.00230,522.7
94.2,1.5501,6.024,0.00231,524.5
94.4,1.5534,6.042,0.00231,526.0
94.6,1.5568,6.061,0.00232,527.7
94.8,1.5600,6.077,0.00232,529.1
95.0,1.5633,6.096,0.00233,530.7
95.2,1.5666,6.114,0.00234,532.3
95.4,1.5700,6.132,0.00234,533.9
95.6,1.5732,6.149,0.00235,535.3
95.8,1.5765,6.168,0.00236,536.9
96.0,1.5796,6.184,0.00237,538.3
96.2,1.5829,6.202,0.00238,540.0
96.4,1.5861,6.219,0.00238,541.4
96.6,1.5896,6.240,0.00239,543.2
96.8,1.5928,6.256,0.00240,544.7
97.0,1.5961,6.277,0.00240,546.4
97.2,1.5994,6.294,0.00241,548.0
97.4,1.6028,6.312,0.00242,549.5
97.6,1.6061,6.332,0.00243,551.2
97.8,1.6095,6.349,0.00244,552.7
98.0,1.6128,6.368,0.00244,554.4
98.2,1.6161,6.387,0.00245,556.1
98.4,1.6196,6.406,0.00245,557.7
98.6,1.6228,6.424,0.00246,559.3
98.8,1.6263,6.444,0.00247,561.0
99.0,1.6296,6.462,0.00247,562.6
99.2,1.6331,6.483,0.00249,564.4
99.4,1.6363,6.500,0.00249,565.8
99.6,1.6397,6.520,0.00250,567.7
99.8,1.6430,6.538,0.00251,569.2
100.0,1.6464,6.558,0.00251,570.9
100.2,1.6498,6.576,0.00252,572.5
100.4,1.6532,6.595,0.00253,574.1
100.6,1.6565,6.614,0.00253,575.8
100.8,1.6599,6.633,0.00254,577.4
101.0,1.6632,6.652,0.00256,579.1
101.2,1.6665,6.670,0.00256,580.7
101.4,1.6700,6.690,0.00257,582.4
101.6,1.6732,6.708,0.00257,584.0
101.8,1.6765,6.726,0.00258,585.6
102.0,1.6796,6.744,0.00259,587.1
102.2,1.6830,6.764,0.00260,588.9
102.4,1.6861,6.782,0.00260,590.5
102.6,1.6895,6.802,0.00261,592.2
102.8,1.6927,6.819,0.00262,593.7
103.0,1.6959,6.838,0.00263,595.3
103.2,1.6992,6.858,0.00264,597.0
103.4,1.7025,6.877,0.00264,598.7
103.6,1.7059,6.896,0.00266,600.4
103.8,1.7092,6.917,0.00266,602.2
104.0,1.7125,6.936,0.00267,603.8
104.2,1.7160,6.956,0.00268,605.6
104.4,1.7192,6.974,0.00268,607.1
104.6,1.7225,6.994,0.00269,608.9
104.8,1.7259,7.012,0.00269,610.4
105.0,1.7292,7.031,0.00271,612.1
105.2,1.7327,7.051,0.00272,613.9
105.4,1.7360,7.070,0.00272,615.5
105.6,1.7393,7.091,0.00273,617.3
105.8,1.7426,7.110,0.00274,619.0
106.0,1.7460,7.130,0.00275,620.7
106.2,1.7492,7.149,0.00276,622.4
106.4,1.7527,7.170,0.00277,624.2
106.6,1.7559,7.188,0.00277,625.7
106.8,1.7593,7.209,0.00278,627.6
107.0,1.7625,7.227,0.00279,629.2
107.2,1.7660,7.248,0.00279,631.0
107.4,1.7693,7.268,0.00280,632.7
107.6,1.7727,7.289,0.00281,634.6
107.8,1.7760,7.307,0.00282,636.1
108.0,1.7792,7.327,0.00282,637.9
108.2,1.7826,7.347,0.00283,639.6
108.4,1.7859,7.365,0.00284,641.2
108.6,1.7892,7.384,0.00285,642.9
108.8,1.7925,7.405,0.00286,644.6
109.0,1.7960,7.424,0.00287,646.4
109.2,1.7992,7.445,0.00287,648.2
109.4,1.8027,7.465,0.00288,649.9
109.6,1.8060,7.485,0.00289,651.7
109.8,1.8094,7.507,0.00290,653.5
110.0,1.8125,7.525,0.00291,655.1
110.2,1.8160,7.546,0.00291,656.9
110.4,1.8192,7.565,0.00292,658.6
110.6,1.8227,7.585,0.00293,660.4
110.8,1.8260,7.605,0.00294,662.1
111.0,1.8294,7.627,0.00294,663.9
111.2,1.8327,7.646,0.00295,665.6
111.4,1.8361,7.668,0.00297,667.5
111.6,1.8394,7.686,0.00297,669.1
111.8,1.8428,7.706,0.00297,670.9
112.0,1.8461,7.726,0.00298,672.6
112.2,1.8493,7.747,0.00299,674.4
112.4,1.8528,7.768,0.00300,676.2
112.6,1.8560,7.788,0.00302,678.0
112.8,1.8593,7.810,0.00302,679.9
113.0,1.8626,7.830,0.00303,681.6
113.2,1.8660,7.850,0.00304,683.4
113.4,1.8692,7.870,0.00305,685.2
113.6,1.8726,7.891,0.00305,687.0
113.8,1.8758,7.911,0.00306,688.7
114.0,1.8792,7.932,0.00307,690.5
114.2,1.8824,7.952,0.00308,692.3
114.4,1.8859,7.974,0.00309,694.2
114.6,1.8891,7.993,0.00309,695.9
114.8,1.8924,8.015,0.00311,697.7
115.0,1.8958,8.035,0.00311,699.5
115.2,1.8991,8.055,0.00312,701.3
115.4,1.9025,8.078,0.00313,703.2
115.6,1.9058,8.098,0.00313,705.0
115.8,1.9092,8.119,0.00314,706.8
116.0,1.9125,8.140,0.00316,708.7
116.2,1.9159,8.161,0.00316,710.5
116.4,1.9191,8.182,0.00317,712.3
116.6,1.9225,8.204,0.00318,714.2
116.8,1.9257,8.223,0.00319,715.9
117.0,1.9292,8.246,0.00319,717.9
117.2,1.9324,8.265,0.00321,719.5
117.4,1.9358,8.287,0.00321,721.4
117.6,1.9390,8.305,0.00322,723.0
117.8,1.9424,8.327,0.00323,724.9
118.0,1.9457,8.347,0.00324,726.7
118.2,1.9491,8.369,0.00324,728.6
118.4,1.9523,8.389,0.00326,730.3
118.6,1.9557,8.411,0.00326,732.2
118.8,1.9588,8.430,0.00327,733.9
119.0,1.9623,8.454,0.00328,736.0
119.2,1.9657,8.474,0.00329,737.8
119.4,1.9691,8.496,0.00331,739.7
119.6,1.9725,8.519,0.00331,741.6
119.8,1.9758,8.540,0.00332,743.5
120.0,1.9792,8.561,0.00332,745.3
120.2,1.9824,8.582,0.00333,747.1
120.4,1.9858,8.602,0.00334,748.9
120.6,1.9891,8.624,0.00335,750.8
120.8,1.9924,8.646,0.00336,752.7
121.0,1.9956,8.666,0.00337,754.5
121.2,1.9991,8.689,0.00337,756.4
121.4,2.0023,8.710,0.00338,758.3
121.6,2.0056,8.732,0.00339,760.2
121.8,2.0090,8.753,0.00340,762.0
122.0,2.0124,8.774,0.00341,763.9
122.2,2.0157,8.797,0.00342,765.8
122.4,2.0190,8.817,0.00343,767.6
122.6,2.0224,8.839,0.00344,769.5
122.8,2.0257,8.861,0.00344,771.4
123.0,2.0292,8.883,0.00346,773.3
123.2,2.0324,8.905,0.00346,775.2
123.4,2.0358,8.927,0.00347,777.2
123.6,2.0389,8.947,0.00348,778.9
123.8,2.0423,8.970,0.00350,780.9
124.0,2.0454,8.987,0.00350,782.4
124.2,2.0488,9.011,0.00351,784.5
124.4,2.0520,9.031,0.00351,786.2
124.6,2.0553,9.054,0.00352,788.2
124.8,2.0586,9.075,0.00353,790.0
125.0,2.0621,9.098,0.00355,792.1
125.2,2.0653,9.120,0.00355,794.0
125.4,2.0688,9.143,0.00356,795.9
125.6,2.0720,9.163,0.00357,797.7
125.8,2.0755,9.187,0.00358,799.8
126.0,2.0789,9.209,0.00359,801.7
126.2,2.0823,9.231,0.00360,803.6
126.4,2.0856,9.254,0.00361,805.6
126.6,2.0889,9.274,0.00362,807.4
126.8,2.0923,9.297,0.00362,809.4
127.0,2.0956,9.319,0.00364,811.3
127.2,2.0988,9.341,0.00365,813.2
127.4,2.1022,9.363,0.00365,815.1
127.6,2.1055,9.385,0.00366,817.0
127.8,2.1088,9.407,0.00367,818.9
128.0,2.1121,9.429,0.00368,820.9
128.2,2.1153,9.450,0.00369,822.7
128.4,2.1187,9.474,0.00369,824.8
128.6,2.1220,9.495,0.00371,826.6
128.8,2.1253,9.518,0.00371,828.6
129.0,2.1286,9.540,0.00373,830.6
129.2,2.1320,9.562,0.00374,832.4
129.4,2.1353,9.585,0.00374,834.4
129.6,2.1386,9.607,0.00375,836.4
129.8,2.1420,9.630,0.00376,838.4
130.0,2.1453,9.652,0.00377,840.3
130.2,2.1488,9.675,0.00378,842.3
130.4,2.1520,9.697,0.00379,844.2
130.6,2.1553,9.720,0.00379,846.2
130.8,2.1585,9.741,0.00380,848.0
131.0,2.1620,9.764,0.00381,850.0
131.2,2.1653,9.786,0.00382,852.0
131.4,2.1688,9.810,0.00383,854.1
131.6,2.1720,9.832,0.00385,856.0
131.8,2.1753,9.856,0.00385,858.0
132.0,2.1786,9.877,0.00386,859.9
132.2,2.1819,9.900,0.00387,861.9
132.4,2.1852,9.922,0.00388,863.8
132.6,2.1885,9.945,0.00389,865.8
132.8,2.1920,9.968,0.00390,867.8
133.0,2.1953,9.991,0.00391,869.8
133.2,2.1987,10.015,0.00392,871.9
133.4,2.2020,10.038,0.00392,873.9
133.6,2.2055,10.062,0.00393,875.9
133.8,2.2086,10.083,0.00394,877.8
134.0,2.2120,10.108,0.00395,880.0
134.2,2.2153,10.129,0.00397,881.8
134.4,2.2187,10.152,0.00397,883.9
134.6,2.2220,10.175,0.00398,885.8
134.8,2.2254,10.200,0.00399,887.9
135.0,2.2287,10.223,0.00400,890.0
135.2,2.2321,10.247,0.00401,892.1
135.4,2.2353,10.268,0.00402,893.9
135.6,2.2387,10.293,0.00403,896.1
135.8,2.2420,10.315,0.00404,898.0
136.0,2.2454,10.339,0.00405,900.1
136.2,2.2488,10.363,0.00406,902.2
136.4,2.2520,10.387,0.00407,904.3
136.6,2.2553,10.412,0.00408,906.4
136.8,2.2586,10.434,0.00409,908.3
137.0,2.2618,10.458,0.00410,910.4
137.2,2.2652,10.481,0.00410,912.5
137.4,2.2684,10.505,0.00412,914.5
137.6,2.2717,10.529,0.00413,916.6
137.8,2.2752,10.553,0.00414,918.7
138.0,2.2784,10.576,0.00414,920.8
138.2,2.2818,10.602,0.00416,923.0
138.4,2.2851,10.625,0.00417,925.0
138.6,2.2883,10.650,0.00418,927.1
138.8,2.2917,10.674,0.00419,929.2
139.0,2.2950,10.697,0.00419,931.3
139.2,2.2984,10.723,0.00420,933.5
139.4,2.3019,10.747,0.00421,935.6
139.6,2.3052,10.772,0.00423,937.8
139.8,2.3085,10.795,0.00424,939.8
140.0,2.3120,10.821,0.00425,942.0
140.2,2.3150,10.842,0.00426,943.9
140.4,2.3185,10.868,0.00427,946.1
140.6,2.3216,10.889,0.00428,948.0
140.8,2.3251,10.915,0.00429,950.3
141.0,2.3284,10.938,0.00430,952.2
141.2,2.3317,10.963,0.00431,954.4
141.4,2.3349,10.986,0.00432,956.4
141.6,2.3384,11.012,0.00433,958.7
141.8,2.3416,11.036,0.00434,960.7
142.0,2.3451,11.061,0.00435,963.0
142.2,2.3484,11.084,0.00436,964.9
142.4,2.3517,11.109,0.00437,967.1
142.6,2.3551,11.132,0.00438,969.1
142.8,2.3584,11.156,0.00439,971.2
143.0,2.3617,11.181,0.00440,973.4
143.2,2.3651,11.205,0.00441,975.5
143.4,2.3684,11.230,0.00442,977.7
143.6,2.3717,11.254,0.00443,979.7
143.8,2.3750,11.278,0.00444,981.8
144.0,2.3784,11.302,0.00444,983.9
144.2,2.3817,11.325,0.00445,986.0
144.4,2.3849,11.350,0.00447,988.1
144.6,2.3884,11.375,0.00448,990.3
144.8,2.3916,11.397,0.00449,992.2
145.0,2.3950,11.423,0.00450,994.5
145.2,2.3983,11.446,0.00451,996.5
145.4,2.4015,11.470,0.00451,998.6
145.6,2.4049,11.494,0.00453,1000.7
145.8,2.4081,11.517,0.00454,1002.6
146.0,2.4115,11.542,0.00454,1004.9
146.2,2.4148,11.566,0.00456,1006.9
146.4,2.4181,11.590,0.00457,1009.0
146.6,2.4215,11.615,0.00458,1011.2
146.8,2.4249,11.639,0.00459,1013.3
147.0,2.4282,11.664,0.00460,1015.4
147.2,2.4317,11.689,0.00461,1017.7
147.4,2.4348,11.710,0.00461,1019.5
147.6,2.4383,11.736,0.00463,1021.7
147.8,2.4415,11.756,0.00463,1023.4
148.0,2.4449,11.781,0.00464,1025.7
148.2,2.4481,11.804,0.00466,1027.6
148.4,2.4516,11.830,0.00467,1029.8
148.6,2.4548,11.852,0.00468,1031.8
148.8,2.4582,11.878,0.00469,1034.0
149.0,2.4613,11.900,0.00469,1036.0
149.2,2.4648,11.925,0.00471,1038.1
149.4,2.4680,11.947,0.00472,1040.1
149.6,2.4713,11.972,0.00472,1042.2
149.8,2.4748,11.997,0.00474,1044.4
150.0,2.4780,12.020,0.00474,1046.5
150.2,2.4815,12.045,0.00476,1048.6
150.4,2.4848,12.068,0.00477,1050.6
150.6,2.4881,12.093,0.00478,1052.8
150.8,2.4914,12.117,0.00479,1054.9
151.0,2.4948,12.141,0.00479,1057.0
151.2,2.4981,12.165,0.00481,1059.1
151.4,2.5016,12.190,0.00482,1061.2
151.6,2.5048,12.213,0.00483,1063.2
151.8,2.5082,12.238,0.00484,1065.4
152.0,2.5115,12.261,0.00485,1067.4
152.2,2.5148,12.286,0.00486,1069.6
152.4,2.5181,12.309,0.00487,1071.6
152.6,2.5213,12.332,0.00488,1073.6
152.8,2.5247,12.355,0.00489,1075.6
153.0,2.5280,12.379,0.00490,1077.7
153.2,2.5314,12.403,0.00491,1079.8
153.4,2.5347,12.427,0.00492,1081.9
153.6,2.5380,12.451,0.00493,1084.0
153.8,2.5413,12.475,0.00494,1086.0
154.0,2.5447,12.500,0.00495,1088.2
154.2,2.5479,12.523,0.00496,1090.2
154.4,2.5513,12.548,0.00497,1092.4
154.6,2.5545,12.571,0.00499,1094.4
154.8,2.5580,12.596,0.00499,1096.6
155.0,2.5612,12.619,0.00500,1098.5
155.2,2.5647,12.644,0.00501,1100.8
155.4,2.5679,12.667,0.00502,1102.8
155.6,2.5712,12.693,0.00503,1105.0
155.8,2.5745,12.716,0.00504,1107.1
156.0,2.5779,12.739,0.00505,1109.1
156.2,2.5812,12.763,0.00507,1111.2
156.4,2.5846,12.788,0.00507,1113.3
156.6,2.5880,12.813,0.00509,1115.4
156.8,2.5914,12.838,0.00510,1117.6
157.0,2.5948,12.862,0.00511,1119.8
157.2,2.5980,12.886,0.00512,1121.8
157.4,2.6015,12.911,0.00513,1124.0
157.6,2.6047,12.933,0.00514,1125.9
157.8,2.6080,12.957,0.00515,1128.0
158.0,2.6112,12.979,0.00516,1129.9
158.2,2.6145,13.003,0.00516,1132.0
158.4,2.6177,13.026,0.00518,1134.0
158.6,2.6212,13.050,0.00519,1136.1
158.8,2.6244,13.073,0.00520,1138.1
159.0,2.6277,13.098,0.00521,1140.2
159.2,2.6309,13.121,0.00522,1142.3
159.4,2.6344,13.146,0.00523,1144.4
159.6,2.6376,13.168,0.00524,1146.4
159.8,2.6409,13.193,0.00525,1148.6
160.0,2.6444,13.217,0.00527,1150.7
160.2,2.6477,13.241,0.00528,1152.8
160.4,2.6511,13.266,0.00528,1154.9
160.6,2.6544,13.289,0.00530,1156.9
160.8,2.6577,13.314,0.00531,1159.1
161.0,2.6611,13.338,0.00532,1161.1
161.2,2.6644,13.362,0.00533,1163.2
161.4,2.6677,13.386,0.00534,1165.4
161.6,2.6711,13.410,0.00535,1167.4
161.8,2.6744,13.433,0.00536,1169.4
162.0,2.6777,13.457,0.00537,1171.6
162.2,2.6809,13.480,0.00538,1173.5
162.4,2.6844,13.505,0.00539,1175.7
162.6,2.6876,13.528,0.00540,1177.7
162.8,2.6909,13.554,0.00541,1179.9
163.0,2.6944,13.576,0.00543,1181.9
163.2,2.6976,13.599,0.00544,1183.9
163.4,2.7010,13.623,0.00545,1186.0
163.6,2.7044,13.646,0.00546,1188.0
163.8,2.7077,13.670,0.00546,1190.1
164.0,2.7111,13.694,0.00548,1192.2
164.2,2.7145,13.719,0.00549,1194.3
164.4,2.7177,13.742,0.00550,1196.4
164.6,2.7212,13.767,0.00551,1198.5
164.8,2.7244,13.790,0.00552,1200.5
165.0,2.7279,13.816,0.00553,1202.8
165.2,2.7311,13.837,0.00554,1204.6
165.4,2.7345,13.862,0.00556,1206.8
165.6,2.7378,13.884,0.00556,1208.7
165.8,2.7412,13.909,0.00557,1210.9
166.0,2.7445,13.932,0.00559,1212.9
166.2,2.7480,13.957,0.00560,1215.1
166.4,2.7511,13.979,0.00561,1216.9
166.6,2.7545,14.003,0.00562,1219.1
166.8,2.7577,14.024,0.00563,1220.9
167.0,2.7611,14.050,0.00565,1223.1
167.2,2.7645,14.072,0.00566,1225.0
167.4,2.7677,14.094,0.00567,1227.0
167.6,2.7710,14.117,0.00568,1229.0
167.8,2.7741,14.139,0.00569,1230.9
168.0,2.7775,14.163,0.00570,1233.0
168.2,2.7807,14.186,0.00571,1235.0
168.4,2.7840,14.211,0.00572,1237.1
168.6,2.7873,14.233,0.00574,1239.1
168.8,2.7906,14.256,0.00574,1241.1
169.0,2.7940,14.280,0.00576,1243.1
169.2,2.7973,14.303,0.00577,1245.2
169.4,2.8006,14.327,0.00578,1247.2
169.6,2.8040,14.352,0.00579,1249.5
169.8,2.8073,14.375,0.00580,1251.4
170.0,2.8105,14.397,0.00582,1253.3
170.2,2.8140,14.422,0.00583,1255.5
170.4,2.8173,14.443,0.00584,1257.4
170.6,2.8208,14.468,0.00584,1259.6
170.8,2.8242,14.492,0.00586,1261.7
171.0,2.8276,14.517,0.00587,1263.8
171.2,2.8309,14.540,0.00588,1265.9
171.4,2.8344,14.566,0.00590,1268.0
171.6,2.8376,14.586,0.00590,1269.8
171.8,2.8410,14.611,0.00592,1272.0
172.0,2.8444,14.632,0.00593,1273.8
172.2,2.8477,14.656,0.00594,1275.9
172.4,2.8510,14.678,0.00596,1277.9
172.6,2.8544,14.703,0.00597,1280.0
172.8,2.8576,14.724,0.00597,1281.8
173.0,2.8611,14.748,0.00599,1283.9
173.2,2.8641,14.769,0.00600,1285.7
173.4,2.8676,14.792,0.00601,1287.8
173.6,2.8706,14.812,0.00602,1289.5
173.8,2.8740,14.836,0.00604,1291.6
174.0,2.8772,14.856,0.00604,1293.3
174.2,2.8805,14.880,0.00606,1295.4
174.4,2.8837,14.900,0.00607,1297.2
174.6,2.8870,14.923,0.00608,1299.2
174.8,2.8904,14.945,0.00610,1301.1
175.0,2.8936,14.968,0.00611,1303.1
175.2,2.8971,14.994,0.00612,1305.3
175.4,2.9004,15.016,0.00613,1307.3
175.6,2.9036,15.039,0.00614,1309.3
175.8,2.9072,15.062,0.00616,1311.3
176.0,2.9104,15.083,0.00617,1313.1
176.2,2.9137,15.106,0.00618,1315.1
176.4,2.9172,15.129,0.00620,1317.1
176.6,2.9204,15.150,0.00621,1319.0
176.8,2.9239,15.175,0.00621,1321.1
177.0,2.9272,15.195,0.00624,1322.9
177.2,2.9304,15.218,0.00624,1324.8
177.4,2.9339,15.240,0.00625,1326.8
177.6,2.9372,15.261,0.00627,1328.6
177.8,2.9405,15.283,0.00628,1330.5
178.0,2.9438,15.305,0.00629,1332.4
178.2,2.9472,15.328,0.00631,1334.4
178.4,2.9505,15.349,0.00632,1336.2
178.6,2.9540,15.373,0.00633,1338.3
178.8,2.9572,15.393,0.00635,1340.1
179.0,2.9606,15.417,0.00636,1342.2
179.2,2.9639,15.435,0.00637,1343.8
179.4,2.9672,15.458,0.00638,1345.8
179.6,2.9704,15.478,0.00640,1347.5
179.8,2.9739,15.501,0.00641,1349.4
180.0,2.9771,15.521,0.00642,1351.2
180.2,2.9804,15.544,0.00644,1353.2
180.4,2.9836,15.564,0.00644,1354.9
180.6,2.9869,15.586,0.00646,1356.8
180.8,2.9903,15.605,0.00647,1358.5
181.0,2.9936,15.626,0.00649,1360.4
181.2,2.9971,15.649,0.00650,1362.3
181.4,3.0004,15.670,0.00651,1364.2
181.6,3.0038,15.692,0.00652,1366.1
181.8,3.0071,15.713,0.00654,1367.9
182.0,3.0104,15.734,0.00655,1369.8
182.2,3.0137,15.755,0.00656,1371.6
182.4,3.0171,15.775,0.00658,1373.3
182.6,3.0204,15.795,0.00659,1375.1
182.8,3.0238,15.817,0.00660,1377.0
183.0,3.0271,15.836,0.00662,1378.7
183.2,3.0305,15.858,0.00663,1380.6
183.4,3.0337,15.878,0.00665,1382.3
183.6,3.0371,15.899,0.00666,1384.1
183.8,3.0403,15.918,0.00667,1385.8
184.0,3.0436,15.938,0.00669,1387.5
184.2,3.0469,15.957,0.00669,1389.2
184.4,3.0503,15.977,0.00671,1390.9
184.6,3.0537,15.998,0.00672,1392.8
184.8,3.0569,16.018,0.00673,1394.5
185.0,3.0604,16.039,0.00675,1396.3
185.2,3.0636,16.058,0.00676,1398.0
185.4,3.0669,16.079,0.00678,1399.8
185.6,3.0702,16.098,0.00679,1401.5
185.8,3.0736,16.119,0.00680,1403.3
186.0,3.0768,16.137,0.00682,1404.9
186.2,3.0801,16.157,0.00683,1406.6
186.4,3.0835,16.177,0.00684,1408.3
186.6,3.0870,16.198,0.00686,1410.1
186.8,3.0903,16.217,0.00687,1411.9
187.0,3.0936,16.237,0.00689,1413.6
187.2,3.0970,16.257,0.00690,1415.3
187.4,3.1003,16.274,0.00692,1416.8
187.6,3.1036,16.294,0.00693,1418.5
187.8,3.1070,16.312,0.00694,1420.1
188.0,3.1104,16.333,0.00696,1421.9
188.2,3.1137,16.351,0.00696,1423.5
188.4,3.1172,16.372,0.00698,1425.3
188.6,3.1203,16.389,0.00700,1426.8
188.8,3.1237,16.410,0.00701,1428.7
189.0,3.1269,16.425,0.00702,1429.9
189.2,3.1303,16.445,0.00704,1431.6
189.4,3.1336,16.461,0.00704,1433.1
189.6,3.1369,16.481,0.00706,1434.8
189.8,3.1402,16.499,0.00708,1436.3
190.0,3.1436,16.518,0.00709,1438.1
190.2,3.1468,16.535,0.00711,1439.5
190.4,3.1502,16.554,0.00713,1441.2
190.6,3.1533,16.570,0.00714,1442.6
190.8,3.1568,16.590,0.00715,1444.3
191.0,3.1602,16.607,0.00717,1445.8
191.2,3.1636,16.625,0.00718,1447.4
191.4,3.1669,16.645,0.00720,1449.1
191.6,3.1703,16.662,0.00721,1450.6
191.8,3.1735,16.679,0.00723,1452.1
192.0,3.1769,16.697,0.00723,1453.6
192.2,3.1801,16.713,0.00725,1455.0
192.4,3.1835,16.731,0.00727,1456.6
192.6,3.1868,16.747,0.00728,1458.0
192.8,3.1901,16.764,0.00730,1459.4
193.0,3.1935,16.781,0.00732,1460.9
193.2,3.1968,16.797,0.00733,1462.3
193.4,3.2001,16.815,0.00735,1463.9
193.6,3.2035,16.830,0.00736,1465.2
193.8,3.2068,16.846,0.00738,1466.5
194.0,3.2102,16.863,0.00739,1468.1
194.2,3.2136,16.878,0.00741,1469.4
194.4,3.2169,16.896,0.00742,1470.9
194.6,3.2203,16.912,0.00744,1472.3
194.8,3.2237,16.928,0.00745,1473.8
195.0,3.2269,16.943,0.00747,1475.1
195.2,3.2304,16.960,0.00749,1476.5
195.4,3.2334,16.973,0.00750,1477.6
195.6,3.2368,16.989,0.00752,1479.0
195.8,3.2399,17.001,0.00753,1480.1
196.0,3.2433,17.019,0.00755,1481.6
196.2,3.2465,17.031,0.00756,1482.6
196.4,3.2500,17.048,0.00758,1484.2
196.6,3.2533,17.062,0.00760,1485.4
196.8,3.2568,17.080,0.00761,1486.9
197.0,3.2599,17.092,0.00763,1488.0
197.2,3.2633,17.108,0.00764,1489.4
197.4,3.2666,17.119,0.00766,1490.4
197.6,3.2700,17.135,0.00768,1491.8
197.8,3.2735,17.150,0.00769,1493.0
198.0,3.2768,17.163,0.00771,1494.2
198.2,3.2802,17.178,0.00773,1495.5
198.4,3.2835,17.191,0.00775,1496.6
198.6,3.2868,17.205,0.00777,1497.8
198.8,3.2901,17.217,0.00778,1498.8
199.0,3.2935,17.228,0.00780,1499.8
199.2,3.2967,17.242,0.00781,1501.0
199.4,3.3001,17.254,0.00783,1502.1
199.6,3.3032,17.265,0.00785,1503.1
199.8,3.3066,17.278,0.00786,1504.2
200.0,3.3098,17.288,0.00788,1505.1
200.2,3.3132,17.301,0.00790,1506.2
200.4,3.3165,17.313,0.00792,1507.2
200.6,3.3197,17.325,0.00793,1508.2
200.8,3.3231,17.337,0.00796,1509.3
201.0,3.3264,17.346,0.00797,1510.1
201.2,3.3298,17.358,0.00799,1511.2
201.4,3.3331,17.369,0.00801,1512.1
201.6,3.3365,17.381,0.00803,1513.1
201.8,3.3399,17.391,0.00804,1514.0
202.0,3.3433,17.403,0.00807,1515.1
202.2,3.3464,17.412,0.00809,1515.9
202.4,3.3499,17.424,0.00811,1516.9
202.6,3.3532,17.431,0.00813,1517.5
202.8,3.3567,17.441,0.00815,1518.4
203.0,3.3600,17.451,0.00817,1519.2
203.2,3.3633,17.461,0.00819,1520.1
203.4,3.3665,17.467,0.00821,1520.7
203.6,3.3699,17.477,0.00824,1521.5
203.8,3.3732,17.485,0.00826,1522.2
204.0,3.3764,17.493,0.00828,1522.9
204.2,3.3798,17.500,0.00830,1523.5
204.4,3.3832,17.508,0.00833,1524.2
204.6,3.3868,17.519,0.00835,1525.1
204.8,3.3900,17.526,0.00837,1525.8
205.0,3.3935,17.535,0.00840,1526.5
205.2,3.3967,17.541,0.00842,1527.1
205.4,3.4000,17.548,0.00845,1527.7
205.6,3.4032,17.553,0.00847,1528.1
205.8,3.4067,17.558,0.00850,1528.6
206.0,3.4100,17.564,0.00852,1529.1
206.2,3.4135,17.573,0.00855,1529.8
206.4,3.4167,17.578,0.00858,1530.3
206.6,3.4201,17.585,0.00860,1530.9
206.8,3.4233,17.587,0.00863,1531.1
207.0,3.4267,17.593,0.00866,1531.6
207.2,3.4301,17.599,0.00869,1532.1
207.4,3.4335,17.603,0.00872,1532.5
207.6,3.4368,17.609,0.00875,1533.0
207.8,3.4400,17.613,0.00877,1533.3
208.0,3.4433,17.618,0.00881,1533.8
208.2,3.4468,17.622,0.00883,1534.1
208.4,3.4500,17.625,0.00886,1534.4
208.6,3.4532,17.629,0.00890,1534.7
208.8,3.4565,17.632,0.00892,1535.0
209.0,3.4597,17.636,0.00896,1535.4
209.2,3.4632,17.640,0.00899,1535.7
209.4,3.4665,17.643,0.00902,1536.0
209.6,3.4698,17.648,0.00905,1536.4
209.8,3.4732,17.650,0.00908,1536.6
210.0,3.4764,17.652,0.00911,1536.7
210.2,3.4798,17.655,0.00914,1537.0
210.4,3.4830,17.657,0.00917,1537.1
210.6,3.4864,17.661,0.00920,1537.6
210.8,3.4898,17.663,0.00924,1537.7
211.0,3.4933,17.667,0.00927,1538.0
211.2,3.4966,17.669,0.00930,1538.2
211.4,3.5000,17.672,0.00933,1538.5
211.6,3.5032,17.673,0.00936,1538.6
211.8,3.5067,17.676,0.00940,1538.9
212.0,3.5097,17.676,0.00943,1538.8
212.2,3.5132,17.679,0.00946,1539.1
212.4,3.5164,17.678,0.00949,1539.0
212.6,3.5199,17.683,0.00952,1539.4
212.8,3.5232,17.682,0.00955,1539.4
213.0,3.5265,17.684,0.00958,1539.5
213.2,3.5297,17.685,0.00961,1539.6
213.4,3.5332,17.689,0.00965,1539.9
213.6,3.5364,17.688,0.00967,1539.9
213.8,3.5400,17.691,0.00971,1540.1
214.0,3.5432,17.689,0.00974,1540.0
214.2,3.5465,17.692,0.00977,1540.2
214.4,3.5500,17.693,0.00980,1540.3
214.6,3.5533,17.693,0.00983,1540.4
214.8,3.5567,17.696,0.00986,1540.6
215.0,3.5600,17.696,0.00989,1540.6
215.2,3.5632,17.697,0.00992,1540.6
215.4,3.5667,17.697,0.00995,1540.7
215.6,3.5699,17.696,0.00998,1540.5
215.8,3.5732,17.698,0.01001,1540.7
216.0,3.5766,17.697,0.01004,1540.6
216.2,3.5799,17.698,0.01007,1540.8
216.4,3.5833,17.699,0.01009,1540.9
216.6,3.5865,17.699,0.01013,1540.8
216.8,3.5900,17.700,0.01016,1541.0
217.0,3.5932,17.699,0.01018,1540.9
217.2,3.5964,17.699,0.01021,1540.8
217.4,3.5999,17.700,0.01024,1540.9
217.6,3.6031,17.698,0.01027,1540.7
217.8,3.6064,17.700,0.01030,1540.9
218.0,3.6097,17.698,0.01032,1540.7
218.2,3.6131,17.699,0.01035,1540.8
218.4,3.6164,17.699,0.01037,1540.8
218.6,3.6199,17.699,0.01040,1540.8
218.8,3.6232,17.700,0.01043,1540.9
219.0,3.6267,17.701,0.01045,1541.0
219.2,3.6297,17.699,0.01048,1540.8
219.4,3.6332,17.701,0.01051,1541.0
219.6,3.6365,17.697,0.01053,1540.6
219.8,3.6399,17.698,0.01055,1540.8
220.0,3.6432,17.697,0.01059,1540.6
220.2,3.6467,17.698,0.01062,1540.7
220.4,3.6500,17.697,0.01063,1540.7
220.6,3.6533,17.696,0.01066,1540.6
220.8,3.6564,17.695,0.01068,1540.5
221.0,3.6600,17.696,0.01071,1540.5
221.2,3.6631,17.692,0.01073,1540.2
221.4,3.6665,17.694,0.01075,1540.4
221.6,3.6699,17.691,0.01078,1540.1
221.8,3.6732,17.691,0.01079,1540.1
222.0,3.6766,17.692,0.01082,1540.2
222.2,3.6800,17.690,0.01084,1540.1
222.4,3.6833,17.691,0.01086,1540.2
222.6,3.6867,17.690,0.01089,1540.1
222.8,3.6900,17.688,0.01091,1539.9
223.0,3.6933,17.688,0.01093,1539.9
223.2,3.6968,17.687,0.01095,1539.8
223.4,3.7000,17.684,0.01097,1539.5
223.6,3.7033,17.684,0.01099,1539.5
223.8,3.7067,17.683,0.01101,1539.4
224.0,3.7099,17.681,0.01103,1539.3
224.2,3.7132,17.680,0.01105,1539.2
224.4,3.7165,17.677,0.01107,1538.9
224.6,3.7199,17.677,0.01108,1538.9
224.8,3.7232,17.675,0.01111,1538.8
225.0,3.7266,17.674,0.01113,1538.6
225.2,3.7299,17.673,0.01114,1538.6
225.4,3.7333,17.672,0.01116,1538.5
225.6,3.7365,17.670,0.01118,1538.3
225.8,3.7400,17.671,0.01120,1538.4
226.0,3.7431,17.668,0.01121,1538.1
226.2,3.7465,17.668,0.01122,1538.2
226.4,3.7498,17.664,0.01124,1537.8
226.6,3.7532,17.664,0.01125,1537.8
226.8,3.7565,17.662,0.01127,1537.6
227.0,3.7599,17.662,0.01128,1537.6
227.2,3.7632,17.660,0.01130,1537.4
227.4,3.7664,17.660,0.01131,1537.4
227.6,3.7697,17.658,0.01133,1537.3
227.8,3.7731,17.655,0.01134,1537.0
228.0,3.7765,17.653,0.01135,1536.8
228.2,3.7800,17.652,0.01137,1536.8
228.4,3.7833,17.652,0.01138,1536.8
228.6,3.7867,17.651,0.01140,1536.7
228.8,3.7901,17.650,0.01141,1536.6
229.0,3.7933,17.648,0.01142,1536.4
229.2,3.7968,17.648,0.01144,1536.4
229.4,3.8000,17.645,0.01144,1536.1
229.6,3.8032,17.644,0.01146,1536.0
229.8,3.8065,17.641,0.01147,1535.8
230.0,3.8099,17.639,0.01148,1535.7
230.2,3.8131,17.638,0.01149,1535.5
230.4,3.8165,17.636,0.01150,1535.3
230.6,3.8197,17.634,0.01151,1535.2
230.8,3.8231,17.634,0.01152,1535.2
231.0,3.8264,17.632,0.01153,1535.0
231.2,3.8297,17.632,0.01154,1535.0
231.4,3.8329,17.630,0.01155,1534.9
231.6,3.8363,17.629,0.01157,1534.8
231.8,3.8396,17.628,0.01157,1534.6
232.0,3.8431,17.626,0.01158,1534.5
232.2,3.8465,17.625,0.01159,1534.4
232.4,3.8498,17.624,0.01160,1534.3
232.6,3.8532,17.624,0.01161,1534.3
232.8,3.8565,17.622,0.01162,1534.1
233.0,3.8600,17.622,0.01164,1534.2
233.2,3.8632,17.619,0.01164,1533.9
233.4,3.8665,17.619,0.01165,1533.9
233.6,3.8698,17.617,0.01166,1533.7
233.8,3.8732,17.615,0.01167,1533.5
234.0,3.8765,17.612,0.01167,1533.3
234.2,3.8800,17.613,0.01169,1533.3
234.4,3.8832,17.611,0.01169,1533.2
234.6,3.8865,17.611,0.01170,1533.1
234.8,3.8900,17.608,0.01171,1532.9
235.0,3.8932,17.606,0.01172,1532.7
235.2,3.8965,17.605,0.01173,1532.7
235.4,3.8999,17.602,0.01174,1532.4
235.6,3.9033,17.602,0.01174,1532.4
235.8,3.9067,17.600,0.01175,1532.2
236.0,3.9101,17.602,0.01176,1532.4
236.2,3.9133,17.599,0.01177,1532.2
236.4,3.9169,17.599,0.01177,1532.1
236.6,3.9200,17.595,0.01178,1531.7
236.8,3.9235,17.595,0.01178,1531.8
237.0,3.9268,17.592,0.01179,1531.5
237.2,3.9302,17.592,0.01180,1531.5
237.4,3.9335,17.589,0.01180,1531.3
237.6,3.9369,17.590,0.01181,1531.3
237.8,3.9400,17.587,0.01181,1531.1
238.0,3.9436,17.587,0.01182,1531.1
238.2,3.9468,17.582,0.01182,1530.7
238.4,3.9501,17.582,0.01183,1530.7
238.6,3.9536,17.580,0.01184,1530.5
238.8,3.9569,17.579,0.01184,1530.3
239.0,3.9601,17.578,0.01185,1530.3
239.2,3.9634,17.575,0.01185,1530.0
239.4,3.9665,17.573,0.01186,1529.9
239.6,3.9698,17.570,0.01186,1529.6
239.8,3.9730,17.570,0.01187,1529.6
240.0,3.9764,17.569,0.01187,1529.5
240.2,3.9796,17.567,0.01188,1529.4
240.4,3.9829,17.567,0.01188,1529.4
240.6,3.9863,17.565,0.01189,1529.2
240.8,3.9896,17.564,0.01189,1529.1
241.0,3.9929,17.562,0.01190,1528.9
241.2,3.9962,17.560,0.01190,1528.8
241.4,3.9996,17.560,0.01190,1528.8
241.6,4.0029,17.558,0.01191,1528.5
241.8,4.0062,17.558,0.01192,1528.5
242.0,4.0097,17.556,0.01193,1528.4
242.2,4.0130,17.552,0.01192,1528.1
242.4,4.0164,17.553,0.01193,1528.1
242.6,4.0199,17.551,0.01193,1527.9
242.8,4.0234,17.550,0.01193,1527.9
243.0,4.0266,17.548,0.01194,1527.6
243.2,4.0301,17.547,0.01195,1527.6
243.4,4.0332,17.542,0.01195,1527.2
243.6,4.0368,17.543,0.01195,1527.2
243.8,4.0401,17.538,0.01195,1526.8
259.8,4.0411,17.137,0.17100,1491.9
260.0,4.0436,17.164,0.17100,1494.3
260.2,4.0468,17.206,0.17101,1497.9
260.4,4.0503,17.251,0.17101,1501.8
260.6,4.0536,17.291,0.17101,1505.3
260.8,4.0569,17.331,0.17101,1508.8
261.0,4.0600,17.365,0.17101,1511.8
261.2,4.0634,17.400,0.17101,1514.8
261.4,4.0664,17.429,0.17101,1517.3
261.6,4.0699,17.460,0.17101,1520.0
261.8,4.0730,17.483,0.17101,1522.0
262.0,4.0764,17.508,0.17101,1524.2
262.2,4.0797,17.526,0.17100,1525.7
262.4,4.0829,17.541,0.17101,1527.1
262.6,4.0864,17.554,0.17101,1528.2
262.8,4.0897,17.562,0.17101,1528.9
263.0,4.0929,17.569,0.17101,1529.5
263.2,4.0964,17.571,0.17102,1529.7
263.4,4.0997,17.569,0.17102,1529.5
263.6,4.1030,17.568,0.17102,1529.4
263.8,4.1064,17.564,0.17102,1529.1
264.0,4.1097,17.560,0.17102,1528.7
264.2,4.1131,17.556,0.17102,1528.4
264.4,4.1165,17.550,0.17102,1527.8
264.6,4.1197,17.544,0.17102,1527.3
264.8,4.1231,17.539,0.17101,1526.9
265.0,4.1264,17.532,0.17101,1526.3
265.2,4.1297,17.527,0.17101,1525.8
265.4,4.1331,17.522,0.17101,1525.4
265.6,4.1365,17.518,0.17101,1525.0
265.8,4.1398,17.513,0.17101,1524.6
266.0,4.1433,17.511,0.17101,1524.5
266.2,4.1464,17.506,0.17101,1524.0
266.4,4.1499,17.504,0.17101,1523.8
266.6,4.1531,17.497,0.17101,1523.2
266.8,4.1565,17.495,0.17101,1523.0
267.0,4.1597,17.489,0.17101,1522.6
267.2,4.1631,17.486,0.17101,1522.3
267.4,4.1664,17.482,0.17101,1522.0
267.6,4.1697,17.481,0.17101,1521.8
267.8,4.1730,17.477,0.17101,1521.5
268.0,4.1764,17.475,0.17101,1521.4
268.2,4.1796,17.471,0.17101,1521.0
268.4,4.1830,17.471,0.17101,1520.9
268.6,4.1863,17.465,0.17101,1520.5
268.8,4.1896,17.463,0.17100,1520.3
269.0,4.1931,17.462,0.17101,1520.2
269.2,4.1964,17.459,0.17101,1519.9
269.4,4.1998,17.458,0.17101,1519.8
269.6,4.2031,17.454,0.17100,1519.5
269.8,4.2064,17.453,0.17101,1519.5
270.0,4.2098,17.451,0.17100,1519.2
270.2,4.2132,17.448,0.17101,1519.0
270.4,4.2165,17.446,0.17101,1518.8
270.6,4.2200,17.444,0.17100,1518.6
270.8,4.2233,17.440,0.17100,1518.3
271.0,4.2268,17.439,0.17101,1518.2
271.2,4.2300,17.435,0.17100,1517.9
271.4,4.2333,17.432,0.17100,1517.6
271.6,4.2365,17.428,0.17100,1517.2
271.8,4.2399,17.425,0.17100,1516.9
272.0,4.2433,17.422,0.17100,1516.8
272.2,4.2467,17.421,0.17100,1516.6
272.4,4.2501,17.419,0.17100,1516.5
272.6,4.2533,17.417,0.17100,1516.3
272.8,4.2567,17.416,0.17100,1516.2
273.0,4.2599,17.412,0.17101,1515.9
273.2,4.2632,17.410,0.17101,1515.7
273.4,4.2664,17.407,0.17100,1515.4
273.6,4.2698,17.405,0.17099,1515.2
273.8,4.2732,17.402,0.17100,1515.0
274.0,4.2766,17.402,0.17100,1514.9
274.2,4.2799,17.399,0.17100,1514.7
274.4,4.2832,17.397,0.17100,1514.5
274.6,4.2866,17.395,0.17099,1514.4
274.8,4.2898,17.391,0.17100,1514.0
275.0,4.2932,17.389,0.17100,1513.8
275.2,4.2965,17.385,0.17100,1513.5
275.4,4.2999,17.383,0.17100,1513.4
275.6,4.3032,17.382,0.17100,1513.2
275.8,4.3067,17.381,0.17099,1513.1
276.0,4.3099,17.378,0.17100,1512.9
276.2,4.3134,17.378,0.17099,1512.9
276.4,4.3165,17.373,0.17100,1512.5
276.6,4.3200,17.373,0.17099,1512.5
276.8,4.3232,17.367,0.17100,1512.0
277.0,4.3265,17.365,0.17099,1511.8
277.2,4.3298,17.362,0.17099,1511.5
277.4,4.3332,17.361,0.17099,1511.4
277.6,4.3365,17.358,0.17099,1511.1
277.8,4.3399,17.357,0.17099,1511.0
278.0,4.3431,17.354,0.17100,1510.8
278.2,4.3465,17.352,0.17099,1510.6
278.4,4.3497,17.348,0.17099,1510.3
278.6,4.3532,17.347,0.17099,1510.2
278.8,4.3566,17.344,0.17099,1509.9
279.0,4.3600,17.341,0.17099,1509.7
279.2,4.3634,17.340,0.17099,1509.6
279.4,4.3667,17.337,0.17099,1509.3
279.6,4.3699,17.335,0.17099,1509.1
279.8,4.3733,17.331,0.17099,1508.8
280.0,4.3766,17.328,0.17099,1508.5
280.2,4.3800,17.326,0.17099,1508.4
280.4,4.3833,17.322,0.17099,1508.0
280.6,4.3865,17.320,0.17099,1507.9
280.8,4.3900,17.318,0.17099,1507.6
281.0,4.3932,17.315,0.17099,1507.4
281.2,4.3965,17.314,0.17099,1507.3
281.4,4.4000,17.312,0.17099,1507.1
281.6,4.4033,17.306,0.17099,1506.6
281.8,4.4067,17.306,0.17099,1506.6
282.0,4.4101,17.302,0.17099,1506.3
282.2,4.4136,17.300,0.17099,1506.1
282.4,4.4168,17.297,0.17098,1505.8
282.6,4.4203,17.295,0.17098,1505.6
282.8,4.4234,17.291,0.17099,1505.3
283.0,4.4269,17.288,0.17099,1505.1
283.2,4.4299,17.282,0.17098,1504.5
283.4,4.4333,17.281,0.17098,1504.5
283.6,4.4364,17.275,0.17099,1503.9
283.8,4.4398,17.275,0.17099,1503.9
284.0,4.4431,17.271,0.17099,1503.6
284.2,4.4465,17.270,0.17098,1503.5
284.4,4.4498,17.266,0.17099,1503.1
284.6,4.4532,17.262,0.17103,1502.8
284.8,4.4564,17.258,0.17102,1502.4
285.0,4.4599,17.258,0.17102,1502.4
285.2,4.4632,17.252,0.17101,1502.0
285.4,4.4665,17.252,0.17102,1501.9
285.6,4.4701,17.249,0.17101,1501.7
285.8,4.4734,17.246,0.17101,1501.4
286.0,4.4768,17.243,0.17102,1501.2
286.2,4.4800,17.239,0.17102,1500.8
286.4,4.4833,17.235,0.17102,1500.5
286.6,4.4867,17.232,0.17102,1500.2
286.8,4.4900,17.227,0.17102,1499.8
287.0,4.4932,17.225,0.17102,1499.5
287.2,4.4967,17.222,0.17101,1499.3
287.4,4.4999,17.217,0.17102,1498.8
287.6,4.5032,17.214,0.17101,1498.6
287.8,4.5065,17.209,0.17102,1498.1
288.0,4.5097,17.206,0.17102,1497.9
288.2,4.5132,17.202,0.17101,1497.6
288.4,4.5164,17.197,0.17102,1497.2
288.6,4.5197,17.195,0.17102,1497.0
288.8,4.5231,17.190,0.17102,1496.5
289.0,4.5265,17.186,0.17102,1496.2
289.2,4.5299,17.183,0.17102,1495.9
289.4,4.5333,17.180,0.17101,1495.6
289.6,4.5366,17.175,0.17101,1495.3
289.8,4.5400,17.172,0.17101,1495.0
290.0,4.5432,17.165,0.17101,1494.4
290.2,4.5467,17.162,0.17102,1494.1
290.4,4.5500,17.156,0.17102,1493.6
290.6,4.5534,17.152,0.17102,1493.2
290.8,4.5566,17.147,0.17101,1492.8
291.0,4.5600,17.143,0.17101,1492.5
291.2,4.5632,17.137,0.17102,1491.9
291.4,4.5665,17.132,0.17101,1491.5
291.6,4.5698,17.126,0.17102,1491.0
291.8,4.5733,17.121,0.17101,1490.6
292.0,4.5768,17.118,0.17101,1490.3
292.2,4.5801,17.113,0.17101,1489.8
292.4,4.5835,17.108,0.17101,1489.4
292.6,4.5868,17.102,0.17101,1488.9
292.8,4.5901,17.097,0.17101,1488.4
293.0,4.5934,17.091,0.17101,1487.9
293.2,4.5967,17.085,0.17101,1487.4
293.4,4.6000,17.078,0.17101,1486.8
293.6,4.6035,17.072,0.17101,1486.3
293.8,4.6068,17.066,0.17101,1485.7
294.0,4.6102,17.061,0.17101,1485.3
294.2,4.6134,17.053,0.17101,1484.6
294.4,4.6168,17.047,0.17101,1484.1
294.6,4.6200,17.038,0.17101,1483.3
294.8,4.6233,17.032,0.17101,1482.7
295.0,4.6267,17.023,0.17101,1482.0
295.2,4.6300,17.014,0.17101,1481.2
295.4,4.6335,17.007,0.17101,1480.6
295.6,4.6368,17.000,0.17101,1480.0
295.8,4.6401,16.993,0.17101,1479.4
296.0,4.6434,16.983,0.17101,1478.5
296.2,4.6466,16.975,0.17101,1477.8
296.4,4.6500,16.965,0.17101,1476.9
296.6,4.6532,16.956,0.17101,1476.2
296.8,4.6565,16.947,0.17101,1475.4
297.0,4.6598,16.937,0.17101,1474.5
297.2,4.6631,16.927,0.17101,1473.6
297.4,4.6666,16.916,0.17101,1472.7
297.6,4.6699,16.905,0.17101,1471.7
297.8,4.6733,16.895,0.17101,1470.8
298.0,4.6767,16.882,0.17101,1469.7
298.2,4.6799,16.869,0.17101,1468.6
298.4,4.6833,16.857,0.17100,1467.5
298.6,4.6867,16.841,0.17101,1466.2
298.8,4.6900,16.828,0.17101,1465.0
299.0,4.6934,16.812,0.17101,1463.7
299.2,4.6968,16.798,0.17101,1462.4
299.4,4.7001,16.782,0.17100,1461.0
299.6,4.7036,16.767,0.17101,1459.7
299.8,4.7068,16.750,0.17100,1458.2
300.0,4.7102,16.734,0.17101,1456.8
300.2,4.7133,16.715,0.17100,1455.1
300.4,4.7168,16.698,0.17101,1453.6
300.6,4.7200,16.676,0.17101,1451.8
300.8,4.7233,16.657,0.17100,1450.1
301.0,4.7265,16.635,0.17101,1448.2
301.2,4.7300,16.614,0.17101,1446.4
301.4,4.7333,16.592,0.17101,1444.4
301.6,4.7368,16.570,0.17101,1442.6
301.8,4.7400,16.544,0.17100,1440.3
302.0,4.7436,16.519,0.17101,1438.1
302.2,4.7468,16.489,0.17101,1435.5
302.4,4.7501,16.463,0.17101,1433.2
302.6,4.7536,16.431,0.17100,1430.5
302.8,4.7569,16.402,0.17101,1427.9
303.0,4.7603,16.372,0.17101,1425.3
303.2,4.7636,16.340,0.17101,1422.5
303.4,4.7669,16.307,0.17101,1419.7
303.6,4.7703,16.272,0.17101,1416.6
303.8,4.7736,16.237,0.17101,1413.6
304.0,4.7770,16.200,0.17101,1410.3
304.2,4.7803,16.159,0.17101,1406.8
304.4,4.7836,16.119,0.17101,1403.3
304.6,4.7871,16.075,0.17101,1399.5
304.8,4.7903,16.030,0.17101,1395.5
305.0,4.7937,15.983,0.17101,1391.5
305.2,4.7969,15.933,0.17101,1387.1
305.4,4.8003,15.885,0.17101,1382.9
305.6,4.8037,15.830,0.17101,1378.1
305.8,4.8069,15.773,0.17101,1373.2
306.0,4.8104,15.714,0.17101,1368.1
306.2,4.8137,15.648,0.17101,1362.3
306.4,4.8171,15.581,0.17101,1356.5
306.6,4.8205,15.509,0.17101,1350.2
306.8,4.8240,15.433,0.17101,1343.6
307.0,4.8272,15.350,0.17101,1336.3
307.2,4.8307,15.262,0.17101,1328.7
307.4,4.8338,15.163,0.17101,1320.1
307.6,4.8373,15.058,0.17101,1311.0
307.8,4.8406,14.932,0.17101,1300.0
308.0,4.8441,14.784,0.17101,1287.0
308.2,4.8474,14.575,0.17101,1268.8
308.4,4.8509,14.174,0.17101,1234.0